2018-05-12 14:24:22.6854|INFO|Servicio.Helpers.NLogger|JSON
Method: GET
URL: http://localhost:8105/api/books/
Controller : Servicio.Controllers.BooksController
Action : GetBooks
Action Parameters : {"messageFormat":"JSON","messageArguments":[{}]}

2018-05-12 14:24:22.6854|INFO|Servicio.Helpers.NLogger|JSON
Method: GET
URL: http://localhost:8105/api/authors/
Controller : Servicio.Controllers.AuthorsController
Action : GetItems
Action Parameters : {"messageFormat":"JSON","messageArguments":[{"page":1,"top":5,"orderby":"Id","ascending":"asc"}]}

2018-05-12 14:24:23.9824|ERROR|Servicio.Helpers.NLogger|Resolver.Exceptions.ApiException: Se produjo una excepción de tipo 'Resolver.Exceptions.ApiException'.
   en BusinessServices.BookServices.GetAll() en E:\Servicio\Peatonales\PeatonalesRosario\BusinessServices\Services\BookServices.cs:línea 70
   en Servicio.Controllers.BooksController.GetBooks() en E:\Servicio\Peatonales\PeatonalesRosario\PeatonalesRosario\Controllers\BooksController.cs:línea 67
   en lambda_method(Closure , Object , Object[] )
   en System.Web.Http.Controllers.ReflectedHttpActionDescriptor.ActionExecutor.<>c__DisplayClass10.<GetExecutor>b__9(Object instance, Object[] methodParameters)
   en System.Web.Http.Controllers.ReflectedHttpActionDescriptor.ExecuteAsync(HttpControllerContext controllerContext, IDictionary`2 arguments, CancellationToken cancellationToken)
--- Fin del seguimiento de la pila de la ubicación anterior donde se produjo la excepción ---
   en System.Runtime.CompilerServices.TaskAwaiter.ThrowForNonSuccess(Task task)
   en System.Runtime.CompilerServices.TaskAwaiter.HandleNonSuccessAndDebuggerNotification(Task task)
   en System.Web.Http.Controllers.ApiControllerActionInvoker.<InvokeActionAsyncCore>d__0.MoveNext()
--- Fin del seguimiento de la pila de la ubicación anterior donde se produjo la excepción ---
   en System.Runtime.CompilerServices.TaskAwaiter.ThrowForNonSuccess(Task task)
   en System.Runtime.CompilerServices.TaskAwaiter.HandleNonSuccessAndDebuggerNotification(Task task)
   en System.Web.Http.Filters.ActionFilterAttribute.<CallOnActionExecutedAsync>d__5.MoveNext()
--- Fin del seguimiento de la pila de la ubicación anterior donde se produjo la excepción ---
   en System.Web.Http.Filters.ActionFilterAttribute.<CallOnActionExecutedAsync>d__5.MoveNext()
--- Fin del seguimiento de la pila de la ubicación anterior donde se produjo la excepción ---
   en System.Runtime.CompilerServices.TaskAwaiter.ThrowForNonSuccess(Task task)
   en System.Runtime.CompilerServices.TaskAwaiter.HandleNonSuccessAndDebuggerNotification(Task task)
   en System.Web.Http.Filters.ActionFilterAttribute.<ExecuteActionFilterAsyncCore>d__0.MoveNext()
--- Fin del seguimiento de la pila de la ubicación anterior donde se produjo la excepción ---
   en System.Runtime.CompilerServices.TaskAwaiter.ThrowForNonSuccess(Task task)
   en System.Runtime.CompilerServices.TaskAwaiter.HandleNonSuccessAndDebuggerNotification(Task task)
   en System.Web.Http.Filters.ActionFilterAttribute.<CallOnActionExecutedAsync>d__5.MoveNext()
--- Fin del seguimiento de la pila de la ubicación anterior donde se produjo la excepción ---
   en System.Web.Http.Filters.ActionFilterAttribute.<CallOnActionExecutedAsync>d__5.MoveNext()
--- Fin del seguimiento de la pila de la ubicación anterior donde se produjo la excepción ---
   en System.Runtime.CompilerServices.TaskAwaiter.ThrowForNonSuccess(Task task)
   en System.Runtime.CompilerServices.TaskAwaiter.HandleNonSuccessAndDebuggerNotification(Task task)
   en System.Web.Http.Filters.ActionFilterAttribute.<ExecuteActionFilterAsyncCore>d__0.MoveNext()
--- Fin del seguimiento de la pila de la ubicación anterior donde se produjo la excepción ---
   en System.Runtime.CompilerServices.TaskAwaiter.ThrowForNonSuccess(Task task)
   en System.Runtime.CompilerServices.TaskAwaiter.HandleNonSuccessAndDebuggerNotification(Task task)
   en System.Web.Http.Controllers.ActionFilterResult.<ExecuteAsync>d__2.MoveNext()
--- Fin del seguimiento de la pila de la ubicación anterior donde se produjo la excepción ---
   en System.Runtime.CompilerServices.TaskAwaiter.ThrowForNonSuccess(Task task)
   en System.Runtime.CompilerServices.TaskAwaiter.HandleNonSuccessAndDebuggerNotification(Task task)
   en System.Web.Http.Controllers.AuthenticationFilterResult.<ExecuteAsync>d__0.MoveNext()
--- Fin del seguimiento de la pila de la ubicación anterior donde se produjo la excepción ---
   en System.Runtime.CompilerServices.TaskAwaiter.ThrowForNonSuccess(Task task)
   en System.Runtime.CompilerServices.TaskAwaiter.HandleNonSuccessAndDebuggerNotification(Task task)
   en System.Web.Http.Controllers.ExceptionFilterResult.<ExecuteAsync>d__0.MoveNext()
Status Code: InternalServerError
Internal Code: -2146233079
ReasonPhrase: InternalServerError
Message: The model backing the 'ServicioContext' context has changed since the database was created. Consider using Code First Migrations to update the database (http://go.microsoft.com/fwlink/?LinkId=238269).
Method: GET
URL: http://localhost:8105/api/books/
Controller : Servicio.Controllers.BooksController
Action : GetBooks
Action Parameters : {"messageFormat":"Resolver.Exceptions.ApiException: Se produjo una excepción de tipo 'Resolver.Exceptions.ApiException'.\r\n   en BusinessServices.BookServices.GetAll() en E:\\Servicio\\Peatonales\\PeatonalesRosario\\BusinessServices\\Services\\BookServices.cs:línea 70\r\n   en Servicio.Controllers.BooksController.GetBooks() en E:\\Servicio\\Peatonales\\PeatonalesRosario\\PeatonalesRosario\\Controllers\\BooksController.cs:línea 67\r\n   en lambda_method(Closure , Object , Object[] )\r\n   en System.Web.Http.Controllers.ReflectedHttpActionDescriptor.ActionExecutor.<>c__DisplayClass10.<GetExecutor>b__9(Object instance, Object[] methodParameters)\r\n   en System.Web.Http.Controllers.ReflectedHttpActionDescriptor.ExecuteAsync(HttpControllerContext controllerContext, IDictionary`2 arguments, CancellationToken cancellationToken)\r\n--- Fin del seguimiento de la pila de la ubicación anterior donde se produjo la excepción ---\r\n   en System.Runtime.CompilerServices.TaskAwaiter.ThrowForNonSuccess(Task task)\r\n   en System.Runtime.CompilerServices.TaskAwaiter.HandleNonSuccessAndDebuggerNotification(Task task)\r\n   en System.Web.Http.Controllers.ApiControllerActionInvoker.<InvokeActionAsyncCore>d__0.MoveNext()\r\n--- Fin del seguimiento de la pila de la ubicación anterior donde se produjo la excepción ---\r\n   en System.Runtime.CompilerServices.TaskAwaiter.ThrowForNonSuccess(Task task)\r\n   en System.Runtime.CompilerServices.TaskAwaiter.HandleNonSuccessAndDebuggerNotification(Task task)\r\n   en System.Web.Http.Filters.ActionFilterAttribute.<CallOnActionExecutedAsync>d__5.MoveNext()\r\n--- Fin del seguimiento de la pila de la ubicación anterior donde se produjo la excepción ---\r\n   en System.Web.Http.Filters.ActionFilterAttribute.<CallOnActionExecutedAsync>d__5.MoveNext()\r\n--- Fin del seguimiento de la pila de la ubicación anterior donde se produjo la excepción ---\r\n   en System.Runtime.CompilerServices.TaskAwaiter.ThrowForNonSuccess(Task task)\r\n   en System.Runtime.CompilerServices.TaskAwaiter.HandleNonSuccessAndDebuggerNotification(Task task)\r\n   en System.Web.Http.Filters.ActionFilterAttribute.<ExecuteActionFilterAsyncCore>d__0.MoveNext()\r\n--- Fin del seguimiento de la pila de la ubicación anterior donde se produjo la excepción ---\r\n   en System.Runtime.CompilerServices.TaskAwaiter.ThrowForNonSuccess(Task task)\r\n   en System.Runtime.CompilerServices.TaskAwaiter.HandleNonSuccessAndDebuggerNotification(Task task)\r\n   en System.Web.Http.Filters.ActionFilterAttribute.<CallOnActionExecutedAsync>d__5.MoveNext()\r\n--- Fin del seguimiento de la pila de la ubicación anterior donde se produjo la excepción ---\r\n   en System.Web.Http.Filters.ActionFilterAttribute.<CallOnActionExecutedAsync>d__5.MoveNext()\r\n--- Fin del seguimiento de la pila de la ubicación anterior donde se produjo la excepción ---\r\n   en System.Runtime.CompilerServices.TaskAwaiter.ThrowForNonSuccess(Task task)\r\n   en System.Runtime.CompilerServices.TaskAwaiter.HandleNonSuccessAndDebuggerNotification(Task task)\r\n   en System.Web.Http.Filters.ActionFilterAttribute.<ExecuteActionFilterAsyncCore>d__0.MoveNext()\r\n--- Fin del seguimiento de la pila de la ubicación anterior donde se produjo la excepción ---\r\n   en System.Runtime.CompilerServices.TaskAwaiter.ThrowForNonSuccess(Task task)\r\n   en System.Runtime.CompilerServices.TaskAwaiter.HandleNonSuccessAndDebuggerNotification(Task task)\r\n   en System.Web.Http.Controllers.ActionFilterResult.<ExecuteAsync>d__2.MoveNext()\r\n--- Fin del seguimiento de la pila de la ubicación anterior donde se produjo la excepción ---\r\n   en System.Runtime.CompilerServices.TaskAwaiter.ThrowForNonSuccess(Task task)\r\n   en System.Runtime.CompilerServices.TaskAwaiter.HandleNonSuccessAndDebuggerNotification(Task task)\r\n   en System.Web.Http.Controllers.AuthenticationFilterResult.<ExecuteAsync>d__0.MoveNext()\r\n--- Fin del seguimiento de la pila de la ubicación anterior donde se produjo la excepción ---\r\n   en System.Runtime.CompilerServices.TaskAwaiter.ThrowForNonSuccess(Task task)\r\n   en System.Runtime.CompilerServices.TaskAwaiter.HandleNonSuccessAndDebuggerNotification(Task task)\r\n   en System.Web.Http.Controllers.ExceptionFilterResult.<ExecuteAsync>d__0.MoveNext()\r\nStatus Code: InternalServerError\r\nInternal Code: -2146233079\r\nReasonPhrase: InternalServerError\r\nMessage: The model backing the 'ServicioContext' context has changed since the database was created. Consider using Code First Migrations to update the database (http://go.microsoft.com/fwlink/?LinkId=238269).","messageArguments":[]}

2018-05-12 14:24:24.4704|ERROR|Servicio.Helpers.NLogger|Resolver.Exceptions.ApiException: Se produjo una excepción de tipo 'Resolver.Exceptions.ApiException'.
   en BusinessServices.AuthorServices.GetAll(Int32 page, Int32 pageSize, String orderBy, String ascending, Int32& count) en E:\Servicio\Peatonales\PeatonalesRosario\BusinessServices\Services\AuthorServices.cs:línea 95
   en Servicio.Controllers.AuthorsController.<GetItems>d__2.MoveNext() en E:\Servicio\Peatonales\PeatonalesRosario\PeatonalesRosario\Controllers\AuthorsController.cs:línea 41
--- Fin del seguimiento de la pila de la ubicación anterior donde se produjo la excepción ---
   en System.Runtime.CompilerServices.TaskAwaiter.ThrowForNonSuccess(Task task)
   en System.Runtime.CompilerServices.TaskAwaiter.HandleNonSuccessAndDebuggerNotification(Task task)
   en System.Threading.Tasks.TaskHelpersExtensions.<CastToObject>d__3`1.MoveNext()
--- Fin del seguimiento de la pila de la ubicación anterior donde se produjo la excepción ---
   en System.Runtime.CompilerServices.TaskAwaiter.ThrowForNonSuccess(Task task)
   en System.Runtime.CompilerServices.TaskAwaiter.HandleNonSuccessAndDebuggerNotification(Task task)
   en System.Web.Http.Controllers.ApiControllerActionInvoker.<InvokeActionAsyncCore>d__0.MoveNext()
--- Fin del seguimiento de la pila de la ubicación anterior donde se produjo la excepción ---
   en System.Runtime.CompilerServices.TaskAwaiter.ThrowForNonSuccess(Task task)
   en System.Runtime.CompilerServices.TaskAwaiter.HandleNonSuccessAndDebuggerNotification(Task task)
   en System.Web.Http.Filters.ActionFilterAttribute.<CallOnActionExecutedAsync>d__5.MoveNext()
--- Fin del seguimiento de la pila de la ubicación anterior donde se produjo la excepción ---
   en System.Web.Http.Filters.ActionFilterAttribute.<CallOnActionExecutedAsync>d__5.MoveNext()
--- Fin del seguimiento de la pila de la ubicación anterior donde se produjo la excepción ---
   en System.Runtime.CompilerServices.TaskAwaiter.ThrowForNonSuccess(Task task)
   en System.Runtime.CompilerServices.TaskAwaiter.HandleNonSuccessAndDebuggerNotification(Task task)
   en System.Web.Http.Filters.ActionFilterAttribute.<ExecuteActionFilterAsyncCore>d__0.MoveNext()
--- Fin del seguimiento de la pila de la ubicación anterior donde se produjo la excepción ---
   en System.Runtime.CompilerServices.TaskAwaiter.ThrowForNonSuccess(Task task)
   en System.Runtime.CompilerServices.TaskAwaiter.HandleNonSuccessAndDebuggerNotification(Task task)
   en System.Web.Http.Controllers.ActionFilterResult.<ExecuteAsync>d__2.MoveNext()
--- Fin del seguimiento de la pila de la ubicación anterior donde se produjo la excepción ---
   en System.Runtime.CompilerServices.TaskAwaiter.ThrowForNonSuccess(Task task)
   en System.Runtime.CompilerServices.TaskAwaiter.HandleNonSuccessAndDebuggerNotification(Task task)
   en System.Web.Http.Controllers.AuthenticationFilterResult.<ExecuteAsync>d__0.MoveNext()
--- Fin del seguimiento de la pila de la ubicación anterior donde se produjo la excepción ---
   en System.Runtime.CompilerServices.TaskAwaiter.ThrowForNonSuccess(Task task)
   en System.Runtime.CompilerServices.TaskAwaiter.HandleNonSuccessAndDebuggerNotification(Task task)
   en System.Web.Http.Controllers.ExceptionFilterResult.<ExecuteAsync>d__0.MoveNext()
Status Code: InternalServerError
Internal Code: -2146233079
ReasonPhrase: InternalServerError
Message: The model backing the 'ServicioContext' context has changed since the database was created. Consider using Code First Migrations to update the database (http://go.microsoft.com/fwlink/?LinkId=238269).
Method: GET
URL: http://localhost:8105/api/authors/
Controller : Servicio.Controllers.AuthorsController
Action : GetItems
Action Parameters : {"messageFormat":"Resolver.Exceptions.ApiException: Se produjo una excepción de tipo 'Resolver.Exceptions.ApiException'.\r\n   en BusinessServices.AuthorServices.GetAll(Int32 page, Int32 pageSize, String orderBy, String ascending, Int32& count) en E:\\Servicio\\Peatonales\\PeatonalesRosario\\BusinessServices\\Services\\AuthorServices.cs:línea 95\r\n   en Servicio.Controllers.AuthorsController.<GetItems>d__2.MoveNext() en E:\\Servicio\\Peatonales\\PeatonalesRosario\\PeatonalesRosario\\Controllers\\AuthorsController.cs:línea 41\r\n--- Fin del seguimiento de la pila de la ubicación anterior donde se produjo la excepción ---\r\n   en System.Runtime.CompilerServices.TaskAwaiter.ThrowForNonSuccess(Task task)\r\n   en System.Runtime.CompilerServices.TaskAwaiter.HandleNonSuccessAndDebuggerNotification(Task task)\r\n   en System.Threading.Tasks.TaskHelpersExtensions.<CastToObject>d__3`1.MoveNext()\r\n--- Fin del seguimiento de la pila de la ubicación anterior donde se produjo la excepción ---\r\n   en System.Runtime.CompilerServices.TaskAwaiter.ThrowForNonSuccess(Task task)\r\n   en System.Runtime.CompilerServices.TaskAwaiter.HandleNonSuccessAndDebuggerNotification(Task task)\r\n   en System.Web.Http.Controllers.ApiControllerActionInvoker.<InvokeActionAsyncCore>d__0.MoveNext()\r\n--- Fin del seguimiento de la pila de la ubicación anterior donde se produjo la excepción ---\r\n   en System.Runtime.CompilerServices.TaskAwaiter.ThrowForNonSuccess(Task task)\r\n   en System.Runtime.CompilerServices.TaskAwaiter.HandleNonSuccessAndDebuggerNotification(Task task)\r\n   en System.Web.Http.Filters.ActionFilterAttribute.<CallOnActionExecutedAsync>d__5.MoveNext()\r\n--- Fin del seguimiento de la pila de la ubicación anterior donde se produjo la excepción ---\r\n   en System.Web.Http.Filters.ActionFilterAttribute.<CallOnActionExecutedAsync>d__5.MoveNext()\r\n--- Fin del seguimiento de la pila de la ubicación anterior donde se produjo la excepción ---\r\n   en System.Runtime.CompilerServices.TaskAwaiter.ThrowForNonSuccess(Task task)\r\n   en System.Runtime.CompilerServices.TaskAwaiter.HandleNonSuccessAndDebuggerNotification(Task task)\r\n   en System.Web.Http.Filters.ActionFilterAttribute.<ExecuteActionFilterAsyncCore>d__0.MoveNext()\r\n--- Fin del seguimiento de la pila de la ubicación anterior donde se produjo la excepción ---\r\n   en System.Runtime.CompilerServices.TaskAwaiter.ThrowForNonSuccess(Task task)\r\n   en System.Runtime.CompilerServices.TaskAwaiter.HandleNonSuccessAndDebuggerNotification(Task task)\r\n   en System.Web.Http.Controllers.ActionFilterResult.<ExecuteAsync>d__2.MoveNext()\r\n--- Fin del seguimiento de la pila de la ubicación anterior donde se produjo la excepción ---\r\n   en System.Runtime.CompilerServices.TaskAwaiter.ThrowForNonSuccess(Task task)\r\n   en System.Runtime.CompilerServices.TaskAwaiter.HandleNonSuccessAndDebuggerNotification(Task task)\r\n   en System.Web.Http.Controllers.AuthenticationFilterResult.<ExecuteAsync>d__0.MoveNext()\r\n--- Fin del seguimiento de la pila de la ubicación anterior donde se produjo la excepción ---\r\n   en System.Runtime.CompilerServices.TaskAwaiter.ThrowForNonSuccess(Task task)\r\n   en System.Runtime.CompilerServices.TaskAwaiter.HandleNonSuccessAndDebuggerNotification(Task task)\r\n   en System.Web.Http.Controllers.ExceptionFilterResult.<ExecuteAsync>d__0.MoveNext()\r\nStatus Code: InternalServerError\r\nInternal Code: -2146233079\r\nReasonPhrase: InternalServerError\r\nMessage: The model backing the 'ServicioContext' context has changed since the database was created. Consider using Code First Migrations to update the database (http://go.microsoft.com/fwlink/?LinkId=238269).","messageArguments":[]}

2018-05-12 14:42:34.9914|INFO|Servicio.Helpers.NLogger|JSON
Method: GET
URL: http://localhost:8105/api/books/
Controller : Servicio.Controllers.BooksController
Action : GetBooks
Action Parameters : {"messageFormat":"JSON","messageArguments":[{}]}

2018-05-12 14:42:34.9914|INFO|Servicio.Helpers.NLogger|JSON
Method: GET
URL: http://localhost:8105/api/authors/
Controller : Servicio.Controllers.AuthorsController
Action : GetItems
Action Parameters : {"messageFormat":"JSON","messageArguments":[{"page":1,"top":5,"orderby":"Id","ascending":"asc"}]}

2018-05-12 14:43:10.5714|ERROR|Servicio.Helpers.NLogger|Resolver.Exceptions.ApiException: Se produjo una excepción de tipo 'Resolver.Exceptions.ApiException'.
   en BusinessServices.BookServices.GetAll() en E:\Servicio\Peatonales\PeatonalesRosario\BusinessServices\Services\BookServices.cs:línea 70
   en Servicio.Controllers.BooksController.GetBooks() en E:\Servicio\Peatonales\PeatonalesRosario\PeatonalesRosario\Controllers\BooksController.cs:línea 67
   en lambda_method(Closure , Object , Object[] )
   en System.Web.Http.Controllers.ReflectedHttpActionDescriptor.ActionExecutor.<>c__DisplayClass10.<GetExecutor>b__9(Object instance, Object[] methodParameters)
   en System.Web.Http.Controllers.ReflectedHttpActionDescriptor.ExecuteAsync(HttpControllerContext controllerContext, IDictionary`2 arguments, CancellationToken cancellationToken)
--- Fin del seguimiento de la pila de la ubicación anterior donde se produjo la excepción ---
   en System.Runtime.CompilerServices.TaskAwaiter.ThrowForNonSuccess(Task task)
   en System.Runtime.CompilerServices.TaskAwaiter.HandleNonSuccessAndDebuggerNotification(Task task)
   en System.Web.Http.Controllers.ApiControllerActionInvoker.<InvokeActionAsyncCore>d__0.MoveNext()
--- Fin del seguimiento de la pila de la ubicación anterior donde se produjo la excepción ---
   en System.Runtime.CompilerServices.TaskAwaiter.ThrowForNonSuccess(Task task)
   en System.Runtime.CompilerServices.TaskAwaiter.HandleNonSuccessAndDebuggerNotification(Task task)
   en System.Web.Http.Filters.ActionFilterAttribute.<CallOnActionExecutedAsync>d__5.MoveNext()
--- Fin del seguimiento de la pila de la ubicación anterior donde se produjo la excepción ---
   en System.Web.Http.Filters.ActionFilterAttribute.<CallOnActionExecutedAsync>d__5.MoveNext()
--- Fin del seguimiento de la pila de la ubicación anterior donde se produjo la excepción ---
   en System.Runtime.CompilerServices.TaskAwaiter.ThrowForNonSuccess(Task task)
   en System.Runtime.CompilerServices.TaskAwaiter.HandleNonSuccessAndDebuggerNotification(Task task)
   en System.Web.Http.Filters.ActionFilterAttribute.<ExecuteActionFilterAsyncCore>d__0.MoveNext()
--- Fin del seguimiento de la pila de la ubicación anterior donde se produjo la excepción ---
   en System.Runtime.CompilerServices.TaskAwaiter.ThrowForNonSuccess(Task task)
   en System.Runtime.CompilerServices.TaskAwaiter.HandleNonSuccessAndDebuggerNotification(Task task)
   en System.Web.Http.Filters.ActionFilterAttribute.<CallOnActionExecutedAsync>d__5.MoveNext()
--- Fin del seguimiento de la pila de la ubicación anterior donde se produjo la excepción ---
   en System.Web.Http.Filters.ActionFilterAttribute.<CallOnActionExecutedAsync>d__5.MoveNext()
--- Fin del seguimiento de la pila de la ubicación anterior donde se produjo la excepción ---
   en System.Runtime.CompilerServices.TaskAwaiter.ThrowForNonSuccess(Task task)
   en System.Runtime.CompilerServices.TaskAwaiter.HandleNonSuccessAndDebuggerNotification(Task task)
   en System.Web.Http.Filters.ActionFilterAttribute.<ExecuteActionFilterAsyncCore>d__0.MoveNext()
--- Fin del seguimiento de la pila de la ubicación anterior donde se produjo la excepción ---
   en System.Runtime.CompilerServices.TaskAwaiter.ThrowForNonSuccess(Task task)
   en System.Runtime.CompilerServices.TaskAwaiter.HandleNonSuccessAndDebuggerNotification(Task task)
   en System.Web.Http.Controllers.ActionFilterResult.<ExecuteAsync>d__2.MoveNext()
--- Fin del seguimiento de la pila de la ubicación anterior donde se produjo la excepción ---
   en System.Runtime.CompilerServices.TaskAwaiter.ThrowForNonSuccess(Task task)
   en System.Runtime.CompilerServices.TaskAwaiter.HandleNonSuccessAndDebuggerNotification(Task task)
   en System.Web.Http.Controllers.AuthenticationFilterResult.<ExecuteAsync>d__0.MoveNext()
--- Fin del seguimiento de la pila de la ubicación anterior donde se produjo la excepción ---
   en System.Runtime.CompilerServices.TaskAwaiter.ThrowForNonSuccess(Task task)
   en System.Runtime.CompilerServices.TaskAwaiter.HandleNonSuccessAndDebuggerNotification(Task task)
   en System.Web.Http.Controllers.ExceptionFilterResult.<ExecuteAsync>d__0.MoveNext()
Status Code: InternalServerError
Internal Code: -2146233088
ReasonPhrase: InternalServerError
Message: Unable to update database to match the current model because there are pending changes and automatic migration is disabled. Either write the pending model changes to a code-based migration or enable automatic migration. Set DbMigrationsConfiguration.AutomaticMigrationsEnabled to true to enable automatic migration.
Method: GET
URL: http://localhost:8105/api/books/
Controller : Servicio.Controllers.BooksController
Action : GetBooks
Action Parameters : {"messageFormat":"Resolver.Exceptions.ApiException: Se produjo una excepción de tipo 'Resolver.Exceptions.ApiException'.\r\n   en BusinessServices.BookServices.GetAll() en E:\\Servicio\\Peatonales\\PeatonalesRosario\\BusinessServices\\Services\\BookServices.cs:línea 70\r\n   en Servicio.Controllers.BooksController.GetBooks() en E:\\Servicio\\Peatonales\\PeatonalesRosario\\PeatonalesRosario\\Controllers\\BooksController.cs:línea 67\r\n   en lambda_method(Closure , Object , Object[] )\r\n   en System.Web.Http.Controllers.ReflectedHttpActionDescriptor.ActionExecutor.<>c__DisplayClass10.<GetExecutor>b__9(Object instance, Object[] methodParameters)\r\n   en System.Web.Http.Controllers.ReflectedHttpActionDescriptor.ExecuteAsync(HttpControllerContext controllerContext, IDictionary`2 arguments, CancellationToken cancellationToken)\r\n--- Fin del seguimiento de la pila de la ubicación anterior donde se produjo la excepción ---\r\n   en System.Runtime.CompilerServices.TaskAwaiter.ThrowForNonSuccess(Task task)\r\n   en System.Runtime.CompilerServices.TaskAwaiter.HandleNonSuccessAndDebuggerNotification(Task task)\r\n   en System.Web.Http.Controllers.ApiControllerActionInvoker.<InvokeActionAsyncCore>d__0.MoveNext()\r\n--- Fin del seguimiento de la pila de la ubicación anterior donde se produjo la excepción ---\r\n   en System.Runtime.CompilerServices.TaskAwaiter.ThrowForNonSuccess(Task task)\r\n   en System.Runtime.CompilerServices.TaskAwaiter.HandleNonSuccessAndDebuggerNotification(Task task)\r\n   en System.Web.Http.Filters.ActionFilterAttribute.<CallOnActionExecutedAsync>d__5.MoveNext()\r\n--- Fin del seguimiento de la pila de la ubicación anterior donde se produjo la excepción ---\r\n   en System.Web.Http.Filters.ActionFilterAttribute.<CallOnActionExecutedAsync>d__5.MoveNext()\r\n--- Fin del seguimiento de la pila de la ubicación anterior donde se produjo la excepción ---\r\n   en System.Runtime.CompilerServices.TaskAwaiter.ThrowForNonSuccess(Task task)\r\n   en System.Runtime.CompilerServices.TaskAwaiter.HandleNonSuccessAndDebuggerNotification(Task task)\r\n   en System.Web.Http.Filters.ActionFilterAttribute.<ExecuteActionFilterAsyncCore>d__0.MoveNext()\r\n--- Fin del seguimiento de la pila de la ubicación anterior donde se produjo la excepción ---\r\n   en System.Runtime.CompilerServices.TaskAwaiter.ThrowForNonSuccess(Task task)\r\n   en System.Runtime.CompilerServices.TaskAwaiter.HandleNonSuccessAndDebuggerNotification(Task task)\r\n   en System.Web.Http.Filters.ActionFilterAttribute.<CallOnActionExecutedAsync>d__5.MoveNext()\r\n--- Fin del seguimiento de la pila de la ubicación anterior donde se produjo la excepción ---\r\n   en System.Web.Http.Filters.ActionFilterAttribute.<CallOnActionExecutedAsync>d__5.MoveNext()\r\n--- Fin del seguimiento de la pila de la ubicación anterior donde se produjo la excepción ---\r\n   en System.Runtime.CompilerServices.TaskAwaiter.ThrowForNonSuccess(Task task)\r\n   en System.Runtime.CompilerServices.TaskAwaiter.HandleNonSuccessAndDebuggerNotification(Task task)\r\n   en System.Web.Http.Filters.ActionFilterAttribute.<ExecuteActionFilterAsyncCore>d__0.MoveNext()\r\n--- Fin del seguimiento de la pila de la ubicación anterior donde se produjo la excepción ---\r\n   en System.Runtime.CompilerServices.TaskAwaiter.ThrowForNonSuccess(Task task)\r\n   en System.Runtime.CompilerServices.TaskAwaiter.HandleNonSuccessAndDebuggerNotification(Task task)\r\n   en System.Web.Http.Controllers.ActionFilterResult.<ExecuteAsync>d__2.MoveNext()\r\n--- Fin del seguimiento de la pila de la ubicación anterior donde se produjo la excepción ---\r\n   en System.Runtime.CompilerServices.TaskAwaiter.ThrowForNonSuccess(Task task)\r\n   en System.Runtime.CompilerServices.TaskAwaiter.HandleNonSuccessAndDebuggerNotification(Task task)\r\n   en System.Web.Http.Controllers.AuthenticationFilterResult.<ExecuteAsync>d__0.MoveNext()\r\n--- Fin del seguimiento de la pila de la ubicación anterior donde se produjo la excepción ---\r\n   en System.Runtime.CompilerServices.TaskAwaiter.ThrowForNonSuccess(Task task)\r\n   en System.Runtime.CompilerServices.TaskAwaiter.HandleNonSuccessAndDebuggerNotification(Task task)\r\n   en System.Web.Http.Controllers.ExceptionFilterResult.<ExecuteAsync>d__0.MoveNext()\r\nStatus Code: InternalServerError\r\nInternal Code: -2146233088\r\nReasonPhrase: InternalServerError\r\nMessage: Unable to update database to match the current model because there are pending changes and automatic migration is disabled. Either write the pending model changes to a code-based migration or enable automatic migration. Set DbMigrationsConfiguration.AutomaticMigrationsEnabled to true to enable automatic migration.","messageArguments":[]}

2018-05-12 14:43:12.2294|ERROR|Servicio.Helpers.NLogger|Resolver.Exceptions.ApiException: Se produjo una excepción de tipo 'Resolver.Exceptions.ApiException'.
   en BusinessServices.AuthorServices.GetAll(Int32 page, Int32 pageSize, String orderBy, String ascending, Int32& count) en E:\Servicio\Peatonales\PeatonalesRosario\BusinessServices\Services\AuthorServices.cs:línea 95
   en Servicio.Controllers.AuthorsController.<GetItems>d__2.MoveNext() en E:\Servicio\Peatonales\PeatonalesRosario\PeatonalesRosario\Controllers\AuthorsController.cs:línea 41
--- Fin del seguimiento de la pila de la ubicación anterior donde se produjo la excepción ---
   en System.Runtime.CompilerServices.TaskAwaiter.ThrowForNonSuccess(Task task)
   en System.Runtime.CompilerServices.TaskAwaiter.HandleNonSuccessAndDebuggerNotification(Task task)
   en System.Threading.Tasks.TaskHelpersExtensions.<CastToObject>d__3`1.MoveNext()
--- Fin del seguimiento de la pila de la ubicación anterior donde se produjo la excepción ---
   en System.Runtime.CompilerServices.TaskAwaiter.ThrowForNonSuccess(Task task)
   en System.Runtime.CompilerServices.TaskAwaiter.HandleNonSuccessAndDebuggerNotification(Task task)
   en System.Web.Http.Controllers.ApiControllerActionInvoker.<InvokeActionAsyncCore>d__0.MoveNext()
--- Fin del seguimiento de la pila de la ubicación anterior donde se produjo la excepción ---
   en System.Runtime.CompilerServices.TaskAwaiter.ThrowForNonSuccess(Task task)
   en System.Runtime.CompilerServices.TaskAwaiter.HandleNonSuccessAndDebuggerNotification(Task task)
   en System.Web.Http.Filters.ActionFilterAttribute.<CallOnActionExecutedAsync>d__5.MoveNext()
--- Fin del seguimiento de la pila de la ubicación anterior donde se produjo la excepción ---
   en System.Web.Http.Filters.ActionFilterAttribute.<CallOnActionExecutedAsync>d__5.MoveNext()
--- Fin del seguimiento de la pila de la ubicación anterior donde se produjo la excepción ---
   en System.Runtime.CompilerServices.TaskAwaiter.ThrowForNonSuccess(Task task)
   en System.Runtime.CompilerServices.TaskAwaiter.HandleNonSuccessAndDebuggerNotification(Task task)
   en System.Web.Http.Filters.ActionFilterAttribute.<ExecuteActionFilterAsyncCore>d__0.MoveNext()
--- Fin del seguimiento de la pila de la ubicación anterior donde se produjo la excepción ---
   en System.Runtime.CompilerServices.TaskAwaiter.ThrowForNonSuccess(Task task)
   en System.Runtime.CompilerServices.TaskAwaiter.HandleNonSuccessAndDebuggerNotification(Task task)
   en System.Web.Http.Controllers.ActionFilterResult.<ExecuteAsync>d__2.MoveNext()
--- Fin del seguimiento de la pila de la ubicación anterior donde se produjo la excepción ---
   en System.Runtime.CompilerServices.TaskAwaiter.ThrowForNonSuccess(Task task)
   en System.Runtime.CompilerServices.TaskAwaiter.HandleNonSuccessAndDebuggerNotification(Task task)
   en System.Web.Http.Controllers.AuthenticationFilterResult.<ExecuteAsync>d__0.MoveNext()
--- Fin del seguimiento de la pila de la ubicación anterior donde se produjo la excepción ---
   en System.Runtime.CompilerServices.TaskAwaiter.ThrowForNonSuccess(Task task)
   en System.Runtime.CompilerServices.TaskAwaiter.HandleNonSuccessAndDebuggerNotification(Task task)
   en System.Web.Http.Controllers.ExceptionFilterResult.<ExecuteAsync>d__0.MoveNext()
Status Code: InternalServerError
Internal Code: -2146233079
ReasonPhrase: InternalServerError
Message: The model backing the 'ServicioContext' context has changed since the database was created. Consider using Code First Migrations to update the database (http://go.microsoft.com/fwlink/?LinkId=238269).
Method: GET
URL: http://localhost:8105/api/authors/
Controller : Servicio.Controllers.AuthorsController
Action : GetItems
Action Parameters : {"messageFormat":"Resolver.Exceptions.ApiException: Se produjo una excepción de tipo 'Resolver.Exceptions.ApiException'.\r\n   en BusinessServices.AuthorServices.GetAll(Int32 page, Int32 pageSize, String orderBy, String ascending, Int32& count) en E:\\Servicio\\Peatonales\\PeatonalesRosario\\BusinessServices\\Services\\AuthorServices.cs:línea 95\r\n   en Servicio.Controllers.AuthorsController.<GetItems>d__2.MoveNext() en E:\\Servicio\\Peatonales\\PeatonalesRosario\\PeatonalesRosario\\Controllers\\AuthorsController.cs:línea 41\r\n--- Fin del seguimiento de la pila de la ubicación anterior donde se produjo la excepción ---\r\n   en System.Runtime.CompilerServices.TaskAwaiter.ThrowForNonSuccess(Task task)\r\n   en System.Runtime.CompilerServices.TaskAwaiter.HandleNonSuccessAndDebuggerNotification(Task task)\r\n   en System.Threading.Tasks.TaskHelpersExtensions.<CastToObject>d__3`1.MoveNext()\r\n--- Fin del seguimiento de la pila de la ubicación anterior donde se produjo la excepción ---\r\n   en System.Runtime.CompilerServices.TaskAwaiter.ThrowForNonSuccess(Task task)\r\n   en System.Runtime.CompilerServices.TaskAwaiter.HandleNonSuccessAndDebuggerNotification(Task task)\r\n   en System.Web.Http.Controllers.ApiControllerActionInvoker.<InvokeActionAsyncCore>d__0.MoveNext()\r\n--- Fin del seguimiento de la pila de la ubicación anterior donde se produjo la excepción ---\r\n   en System.Runtime.CompilerServices.TaskAwaiter.ThrowForNonSuccess(Task task)\r\n   en System.Runtime.CompilerServices.TaskAwaiter.HandleNonSuccessAndDebuggerNotification(Task task)\r\n   en System.Web.Http.Filters.ActionFilterAttribute.<CallOnActionExecutedAsync>d__5.MoveNext()\r\n--- Fin del seguimiento de la pila de la ubicación anterior donde se produjo la excepción ---\r\n   en System.Web.Http.Filters.ActionFilterAttribute.<CallOnActionExecutedAsync>d__5.MoveNext()\r\n--- Fin del seguimiento de la pila de la ubicación anterior donde se produjo la excepción ---\r\n   en System.Runtime.CompilerServices.TaskAwaiter.ThrowForNonSuccess(Task task)\r\n   en System.Runtime.CompilerServices.TaskAwaiter.HandleNonSuccessAndDebuggerNotification(Task task)\r\n   en System.Web.Http.Filters.ActionFilterAttribute.<ExecuteActionFilterAsyncCore>d__0.MoveNext()\r\n--- Fin del seguimiento de la pila de la ubicación anterior donde se produjo la excepción ---\r\n   en System.Runtime.CompilerServices.TaskAwaiter.ThrowForNonSuccess(Task task)\r\n   en System.Runtime.CompilerServices.TaskAwaiter.HandleNonSuccessAndDebuggerNotification(Task task)\r\n   en System.Web.Http.Controllers.ActionFilterResult.<ExecuteAsync>d__2.MoveNext()\r\n--- Fin del seguimiento de la pila de la ubicación anterior donde se produjo la excepción ---\r\n   en System.Runtime.CompilerServices.TaskAwaiter.ThrowForNonSuccess(Task task)\r\n   en System.Runtime.CompilerServices.TaskAwaiter.HandleNonSuccessAndDebuggerNotification(Task task)\r\n   en System.Web.Http.Controllers.AuthenticationFilterResult.<ExecuteAsync>d__0.MoveNext()\r\n--- Fin del seguimiento de la pila de la ubicación anterior donde se produjo la excepción ---\r\n   en System.Runtime.CompilerServices.TaskAwaiter.ThrowForNonSuccess(Task task)\r\n   en System.Runtime.CompilerServices.TaskAwaiter.HandleNonSuccessAndDebuggerNotification(Task task)\r\n   en System.Web.Http.Controllers.ExceptionFilterResult.<ExecuteAsync>d__0.MoveNext()\r\nStatus Code: InternalServerError\r\nInternal Code: -2146233079\r\nReasonPhrase: InternalServerError\r\nMessage: The model backing the 'ServicioContext' context has changed since the database was created. Consider using Code First Migrations to update the database (http://go.microsoft.com/fwlink/?LinkId=238269).","messageArguments":[]}

2018-05-12 14:48:01.1994|INFO|Servicio.Helpers.NLogger|JSON
Method: GET
URL: http://localhost:8105/api/books/
Controller : Servicio.Controllers.BooksController
Action : GetBooks
Action Parameters : {"messageFormat":"JSON","messageArguments":[{}]}

2018-05-12 14:48:01.1994|INFO|Servicio.Helpers.NLogger|JSON
Method: GET
URL: http://localhost:8105/api/authors/
Controller : Servicio.Controllers.AuthorsController
Action : GetItems
Action Parameters : {"messageFormat":"JSON","messageArguments":[{"page":1,"top":5,"orderby":"Id","ascending":"asc"}]}

2018-05-12 14:48:02.7284|ERROR|Servicio.Helpers.NLogger|Resolver.Exceptions.ApiException: Se produjo una excepción de tipo 'Resolver.Exceptions.ApiException'.
   en BusinessServices.AuthorServices.GetAll(Int32 page, Int32 pageSize, String orderBy, String ascending, Int32& count) en E:\Servicio\Peatonales\PeatonalesRosario\BusinessServices\Services\AuthorServices.cs:línea 95
   en Servicio.Controllers.AuthorsController.<GetItems>d__2.MoveNext() en E:\Servicio\Peatonales\PeatonalesRosario\PeatonalesRosario\Controllers\AuthorsController.cs:línea 41
--- Fin del seguimiento de la pila de la ubicación anterior donde se produjo la excepción ---
   en System.Runtime.CompilerServices.TaskAwaiter.ThrowForNonSuccess(Task task)
   en System.Runtime.CompilerServices.TaskAwaiter.HandleNonSuccessAndDebuggerNotification(Task task)
   en System.Threading.Tasks.TaskHelpersExtensions.<CastToObject>d__3`1.MoveNext()
--- Fin del seguimiento de la pila de la ubicación anterior donde se produjo la excepción ---
   en System.Runtime.CompilerServices.TaskAwaiter.ThrowForNonSuccess(Task task)
   en System.Runtime.CompilerServices.TaskAwaiter.HandleNonSuccessAndDebuggerNotification(Task task)
   en System.Web.Http.Controllers.ApiControllerActionInvoker.<InvokeActionAsyncCore>d__0.MoveNext()
--- Fin del seguimiento de la pila de la ubicación anterior donde se produjo la excepción ---
   en System.Runtime.CompilerServices.TaskAwaiter.ThrowForNonSuccess(Task task)
   en System.Runtime.CompilerServices.TaskAwaiter.HandleNonSuccessAndDebuggerNotification(Task task)
   en System.Web.Http.Filters.ActionFilterAttribute.<CallOnActionExecutedAsync>d__5.MoveNext()
--- Fin del seguimiento de la pila de la ubicación anterior donde se produjo la excepción ---
   en System.Web.Http.Filters.ActionFilterAttribute.<CallOnActionExecutedAsync>d__5.MoveNext()
--- Fin del seguimiento de la pila de la ubicación anterior donde se produjo la excepción ---
   en System.Runtime.CompilerServices.TaskAwaiter.ThrowForNonSuccess(Task task)
   en System.Runtime.CompilerServices.TaskAwaiter.HandleNonSuccessAndDebuggerNotification(Task task)
   en System.Web.Http.Filters.ActionFilterAttribute.<ExecuteActionFilterAsyncCore>d__0.MoveNext()
--- Fin del seguimiento de la pila de la ubicación anterior donde se produjo la excepción ---
   en System.Runtime.CompilerServices.TaskAwaiter.ThrowForNonSuccess(Task task)
   en System.Runtime.CompilerServices.TaskAwaiter.HandleNonSuccessAndDebuggerNotification(Task task)
   en System.Web.Http.Controllers.ActionFilterResult.<ExecuteAsync>d__2.MoveNext()
--- Fin del seguimiento de la pila de la ubicación anterior donde se produjo la excepción ---
   en System.Runtime.CompilerServices.TaskAwaiter.ThrowForNonSuccess(Task task)
   en System.Runtime.CompilerServices.TaskAwaiter.HandleNonSuccessAndDebuggerNotification(Task task)
   en System.Web.Http.Controllers.AuthenticationFilterResult.<ExecuteAsync>d__0.MoveNext()
--- Fin del seguimiento de la pila de la ubicación anterior donde se produjo la excepción ---
   en System.Runtime.CompilerServices.TaskAwaiter.ThrowForNonSuccess(Task task)
   en System.Runtime.CompilerServices.TaskAwaiter.HandleNonSuccessAndDebuggerNotification(Task task)
   en System.Web.Http.Controllers.ExceptionFilterResult.<ExecuteAsync>d__0.MoveNext()
Status Code: InternalServerError
Internal Code: -2146233088
ReasonPhrase: InternalServerError
Message: Unable to update database to match the current model because there are pending changes and automatic migration is disabled. Either write the pending model changes to a code-based migration or enable automatic migration. Set DbMigrationsConfiguration.AutomaticMigrationsEnabled to true to enable automatic migration.
Method: GET
URL: http://localhost:8105/api/authors/
Controller : Servicio.Controllers.AuthorsController
Action : GetItems
Action Parameters : {"messageFormat":"Resolver.Exceptions.ApiException: Se produjo una excepción de tipo 'Resolver.Exceptions.ApiException'.\r\n   en BusinessServices.AuthorServices.GetAll(Int32 page, Int32 pageSize, String orderBy, String ascending, Int32& count) en E:\\Servicio\\Peatonales\\PeatonalesRosario\\BusinessServices\\Services\\AuthorServices.cs:línea 95\r\n   en Servicio.Controllers.AuthorsController.<GetItems>d__2.MoveNext() en E:\\Servicio\\Peatonales\\PeatonalesRosario\\PeatonalesRosario\\Controllers\\AuthorsController.cs:línea 41\r\n--- Fin del seguimiento de la pila de la ubicación anterior donde se produjo la excepción ---\r\n   en System.Runtime.CompilerServices.TaskAwaiter.ThrowForNonSuccess(Task task)\r\n   en System.Runtime.CompilerServices.TaskAwaiter.HandleNonSuccessAndDebuggerNotification(Task task)\r\n   en System.Threading.Tasks.TaskHelpersExtensions.<CastToObject>d__3`1.MoveNext()\r\n--- Fin del seguimiento de la pila de la ubicación anterior donde se produjo la excepción ---\r\n   en System.Runtime.CompilerServices.TaskAwaiter.ThrowForNonSuccess(Task task)\r\n   en System.Runtime.CompilerServices.TaskAwaiter.HandleNonSuccessAndDebuggerNotification(Task task)\r\n   en System.Web.Http.Controllers.ApiControllerActionInvoker.<InvokeActionAsyncCore>d__0.MoveNext()\r\n--- Fin del seguimiento de la pila de la ubicación anterior donde se produjo la excepción ---\r\n   en System.Runtime.CompilerServices.TaskAwaiter.ThrowForNonSuccess(Task task)\r\n   en System.Runtime.CompilerServices.TaskAwaiter.HandleNonSuccessAndDebuggerNotification(Task task)\r\n   en System.Web.Http.Filters.ActionFilterAttribute.<CallOnActionExecutedAsync>d__5.MoveNext()\r\n--- Fin del seguimiento de la pila de la ubicación anterior donde se produjo la excepción ---\r\n   en System.Web.Http.Filters.ActionFilterAttribute.<CallOnActionExecutedAsync>d__5.MoveNext()\r\n--- Fin del seguimiento de la pila de la ubicación anterior donde se produjo la excepción ---\r\n   en System.Runtime.CompilerServices.TaskAwaiter.ThrowForNonSuccess(Task task)\r\n   en System.Runtime.CompilerServices.TaskAwaiter.HandleNonSuccessAndDebuggerNotification(Task task)\r\n   en System.Web.Http.Filters.ActionFilterAttribute.<ExecuteActionFilterAsyncCore>d__0.MoveNext()\r\n--- Fin del seguimiento de la pila de la ubicación anterior donde se produjo la excepción ---\r\n   en System.Runtime.CompilerServices.TaskAwaiter.ThrowForNonSuccess(Task task)\r\n   en System.Runtime.CompilerServices.TaskAwaiter.HandleNonSuccessAndDebuggerNotification(Task task)\r\n   en System.Web.Http.Controllers.ActionFilterResult.<ExecuteAsync>d__2.MoveNext()\r\n--- Fin del seguimiento de la pila de la ubicación anterior donde se produjo la excepción ---\r\n   en System.Runtime.CompilerServices.TaskAwaiter.ThrowForNonSuccess(Task task)\r\n   en System.Runtime.CompilerServices.TaskAwaiter.HandleNonSuccessAndDebuggerNotification(Task task)\r\n   en System.Web.Http.Controllers.AuthenticationFilterResult.<ExecuteAsync>d__0.MoveNext()\r\n--- Fin del seguimiento de la pila de la ubicación anterior donde se produjo la excepción ---\r\n   en System.Runtime.CompilerServices.TaskAwaiter.ThrowForNonSuccess(Task task)\r\n   en System.Runtime.CompilerServices.TaskAwaiter.HandleNonSuccessAndDebuggerNotification(Task task)\r\n   en System.Web.Http.Controllers.ExceptionFilterResult.<ExecuteAsync>d__0.MoveNext()\r\nStatus Code: InternalServerError\r\nInternal Code: -2146233088\r\nReasonPhrase: InternalServerError\r\nMessage: Unable to update database to match the current model because there are pending changes and automatic migration is disabled. Either write the pending model changes to a code-based migration or enable automatic migration. Set DbMigrationsConfiguration.AutomaticMigrationsEnabled to true to enable automatic migration.","messageArguments":[]}

2018-05-12 14:48:06.5134|ERROR|Servicio.Helpers.NLogger|Resolver.Exceptions.ApiException: Se produjo una excepción de tipo 'Resolver.Exceptions.ApiException'.
   en BusinessServices.BookServices.GetAll() en E:\Servicio\Peatonales\PeatonalesRosario\BusinessServices\Services\BookServices.cs:línea 70
   en Servicio.Controllers.BooksController.GetBooks() en E:\Servicio\Peatonales\PeatonalesRosario\PeatonalesRosario\Controllers\BooksController.cs:línea 67
   en lambda_method(Closure , Object , Object[] )
   en System.Web.Http.Controllers.ReflectedHttpActionDescriptor.ActionExecutor.<>c__DisplayClass10.<GetExecutor>b__9(Object instance, Object[] methodParameters)
   en System.Web.Http.Controllers.ReflectedHttpActionDescriptor.ExecuteAsync(HttpControllerContext controllerContext, IDictionary`2 arguments, CancellationToken cancellationToken)
--- Fin del seguimiento de la pila de la ubicación anterior donde se produjo la excepción ---
   en System.Runtime.CompilerServices.TaskAwaiter.ThrowForNonSuccess(Task task)
   en System.Runtime.CompilerServices.TaskAwaiter.HandleNonSuccessAndDebuggerNotification(Task task)
   en System.Web.Http.Controllers.ApiControllerActionInvoker.<InvokeActionAsyncCore>d__0.MoveNext()
--- Fin del seguimiento de la pila de la ubicación anterior donde se produjo la excepción ---
   en System.Runtime.CompilerServices.TaskAwaiter.ThrowForNonSuccess(Task task)
   en System.Runtime.CompilerServices.TaskAwaiter.HandleNonSuccessAndDebuggerNotification(Task task)
   en System.Web.Http.Filters.ActionFilterAttribute.<CallOnActionExecutedAsync>d__5.MoveNext()
--- Fin del seguimiento de la pila de la ubicación anterior donde se produjo la excepción ---
   en System.Web.Http.Filters.ActionFilterAttribute.<CallOnActionExecutedAsync>d__5.MoveNext()
--- Fin del seguimiento de la pila de la ubicación anterior donde se produjo la excepción ---
   en System.Runtime.CompilerServices.TaskAwaiter.ThrowForNonSuccess(Task task)
   en System.Runtime.CompilerServices.TaskAwaiter.HandleNonSuccessAndDebuggerNotification(Task task)
   en System.Web.Http.Filters.ActionFilterAttribute.<ExecuteActionFilterAsyncCore>d__0.MoveNext()
--- Fin del seguimiento de la pila de la ubicación anterior donde se produjo la excepción ---
   en System.Runtime.CompilerServices.TaskAwaiter.ThrowForNonSuccess(Task task)
   en System.Runtime.CompilerServices.TaskAwaiter.HandleNonSuccessAndDebuggerNotification(Task task)
   en System.Web.Http.Filters.ActionFilterAttribute.<CallOnActionExecutedAsync>d__5.MoveNext()
--- Fin del seguimiento de la pila de la ubicación anterior donde se produjo la excepción ---
   en System.Web.Http.Filters.ActionFilterAttribute.<CallOnActionExecutedAsync>d__5.MoveNext()
--- Fin del seguimiento de la pila de la ubicación anterior donde se produjo la excepción ---
   en System.Runtime.CompilerServices.TaskAwaiter.ThrowForNonSuccess(Task task)
   en System.Runtime.CompilerServices.TaskAwaiter.HandleNonSuccessAndDebuggerNotification(Task task)
   en System.Web.Http.Filters.ActionFilterAttribute.<ExecuteActionFilterAsyncCore>d__0.MoveNext()
--- Fin del seguimiento de la pila de la ubicación anterior donde se produjo la excepción ---
   en System.Runtime.CompilerServices.TaskAwaiter.ThrowForNonSuccess(Task task)
   en System.Runtime.CompilerServices.TaskAwaiter.HandleNonSuccessAndDebuggerNotification(Task task)
   en System.Web.Http.Controllers.ActionFilterResult.<ExecuteAsync>d__2.MoveNext()
--- Fin del seguimiento de la pila de la ubicación anterior donde se produjo la excepción ---
   en System.Runtime.CompilerServices.TaskAwaiter.ThrowForNonSuccess(Task task)
   en System.Runtime.CompilerServices.TaskAwaiter.HandleNonSuccessAndDebuggerNotification(Task task)
   en System.Web.Http.Controllers.AuthenticationFilterResult.<ExecuteAsync>d__0.MoveNext()
--- Fin del seguimiento de la pila de la ubicación anterior donde se produjo la excepción ---
   en System.Runtime.CompilerServices.TaskAwaiter.ThrowForNonSuccess(Task task)
   en System.Runtime.CompilerServices.TaskAwaiter.HandleNonSuccessAndDebuggerNotification(Task task)
   en System.Web.Http.Controllers.ExceptionFilterResult.<ExecuteAsync>d__0.MoveNext()
Status Code: InternalServerError
Internal Code: -2146233079
ReasonPhrase: InternalServerError
Message: The model backing the 'ServicioContext' context has changed since the database was created. Consider using Code First Migrations to update the database (http://go.microsoft.com/fwlink/?LinkId=238269).
Method: GET
URL: http://localhost:8105/api/books/
Controller : Servicio.Controllers.BooksController
Action : GetBooks
Action Parameters : {"messageFormat":"Resolver.Exceptions.ApiException: Se produjo una excepción de tipo 'Resolver.Exceptions.ApiException'.\r\n   en BusinessServices.BookServices.GetAll() en E:\\Servicio\\Peatonales\\PeatonalesRosario\\BusinessServices\\Services\\BookServices.cs:línea 70\r\n   en Servicio.Controllers.BooksController.GetBooks() en E:\\Servicio\\Peatonales\\PeatonalesRosario\\PeatonalesRosario\\Controllers\\BooksController.cs:línea 67\r\n   en lambda_method(Closure , Object , Object[] )\r\n   en System.Web.Http.Controllers.ReflectedHttpActionDescriptor.ActionExecutor.<>c__DisplayClass10.<GetExecutor>b__9(Object instance, Object[] methodParameters)\r\n   en System.Web.Http.Controllers.ReflectedHttpActionDescriptor.ExecuteAsync(HttpControllerContext controllerContext, IDictionary`2 arguments, CancellationToken cancellationToken)\r\n--- Fin del seguimiento de la pila de la ubicación anterior donde se produjo la excepción ---\r\n   en System.Runtime.CompilerServices.TaskAwaiter.ThrowForNonSuccess(Task task)\r\n   en System.Runtime.CompilerServices.TaskAwaiter.HandleNonSuccessAndDebuggerNotification(Task task)\r\n   en System.Web.Http.Controllers.ApiControllerActionInvoker.<InvokeActionAsyncCore>d__0.MoveNext()\r\n--- Fin del seguimiento de la pila de la ubicación anterior donde se produjo la excepción ---\r\n   en System.Runtime.CompilerServices.TaskAwaiter.ThrowForNonSuccess(Task task)\r\n   en System.Runtime.CompilerServices.TaskAwaiter.HandleNonSuccessAndDebuggerNotification(Task task)\r\n   en System.Web.Http.Filters.ActionFilterAttribute.<CallOnActionExecutedAsync>d__5.MoveNext()\r\n--- Fin del seguimiento de la pila de la ubicación anterior donde se produjo la excepción ---\r\n   en System.Web.Http.Filters.ActionFilterAttribute.<CallOnActionExecutedAsync>d__5.MoveNext()\r\n--- Fin del seguimiento de la pila de la ubicación anterior donde se produjo la excepción ---\r\n   en System.Runtime.CompilerServices.TaskAwaiter.ThrowForNonSuccess(Task task)\r\n   en System.Runtime.CompilerServices.TaskAwaiter.HandleNonSuccessAndDebuggerNotification(Task task)\r\n   en System.Web.Http.Filters.ActionFilterAttribute.<ExecuteActionFilterAsyncCore>d__0.MoveNext()\r\n--- Fin del seguimiento de la pila de la ubicación anterior donde se produjo la excepción ---\r\n   en System.Runtime.CompilerServices.TaskAwaiter.ThrowForNonSuccess(Task task)\r\n   en System.Runtime.CompilerServices.TaskAwaiter.HandleNonSuccessAndDebuggerNotification(Task task)\r\n   en System.Web.Http.Filters.ActionFilterAttribute.<CallOnActionExecutedAsync>d__5.MoveNext()\r\n--- Fin del seguimiento de la pila de la ubicación anterior donde se produjo la excepción ---\r\n   en System.Web.Http.Filters.ActionFilterAttribute.<CallOnActionExecutedAsync>d__5.MoveNext()\r\n--- Fin del seguimiento de la pila de la ubicación anterior donde se produjo la excepción ---\r\n   en System.Runtime.CompilerServices.TaskAwaiter.ThrowForNonSuccess(Task task)\r\n   en System.Runtime.CompilerServices.TaskAwaiter.HandleNonSuccessAndDebuggerNotification(Task task)\r\n   en System.Web.Http.Filters.ActionFilterAttribute.<ExecuteActionFilterAsyncCore>d__0.MoveNext()\r\n--- Fin del seguimiento de la pila de la ubicación anterior donde se produjo la excepción ---\r\n   en System.Runtime.CompilerServices.TaskAwaiter.ThrowForNonSuccess(Task task)\r\n   en System.Runtime.CompilerServices.TaskAwaiter.HandleNonSuccessAndDebuggerNotification(Task task)\r\n   en System.Web.Http.Controllers.ActionFilterResult.<ExecuteAsync>d__2.MoveNext()\r\n--- Fin del seguimiento de la pila de la ubicación anterior donde se produjo la excepción ---\r\n   en System.Runtime.CompilerServices.TaskAwaiter.ThrowForNonSuccess(Task task)\r\n   en System.Runtime.CompilerServices.TaskAwaiter.HandleNonSuccessAndDebuggerNotification(Task task)\r\n   en System.Web.Http.Controllers.AuthenticationFilterResult.<ExecuteAsync>d__0.MoveNext()\r\n--- Fin del seguimiento de la pila de la ubicación anterior donde se produjo la excepción ---\r\n   en System.Runtime.CompilerServices.TaskAwaiter.ThrowForNonSuccess(Task task)\r\n   en System.Runtime.CompilerServices.TaskAwaiter.HandleNonSuccessAndDebuggerNotification(Task task)\r\n   en System.Web.Http.Controllers.ExceptionFilterResult.<ExecuteAsync>d__0.MoveNext()\r\nStatus Code: InternalServerError\r\nInternal Code: -2146233079\r\nReasonPhrase: InternalServerError\r\nMessage: The model backing the 'ServicioContext' context has changed since the database was created. Consider using Code First Migrations to update the database (http://go.microsoft.com/fwlink/?LinkId=238269).","messageArguments":[]}

2018-05-12 14:49:28.8974|INFO|Servicio.Helpers.NLogger|JSON
Method: GET
URL: http://localhost:8105/api/authors/
Controller : Servicio.Controllers.AuthorsController
Action : GetItems
Action Parameters : {"messageFormat":"JSON","messageArguments":[{"page":1,"top":5,"orderby":"Id","ascending":"asc"}]}

2018-05-12 14:49:28.8974|INFO|Servicio.Helpers.NLogger|JSON
Method: GET
URL: http://localhost:8105/api/books/
Controller : Servicio.Controllers.BooksController
Action : GetBooks
Action Parameters : {"messageFormat":"JSON","messageArguments":[{}]}

2018-05-12 14:50:04.2164|ERROR|Servicio.Helpers.NLogger|Resolver.Exceptions.ApiException: Se produjo una excepción de tipo 'Resolver.Exceptions.ApiException'.
   en BusinessServices.BookServices.GetAll() en E:\Servicio\Peatonales\PeatonalesRosario\BusinessServices\Services\BookServices.cs:línea 70
   en Servicio.Controllers.BooksController.GetBooks() en E:\Servicio\Peatonales\PeatonalesRosario\PeatonalesRosario\Controllers\BooksController.cs:línea 67
   en lambda_method(Closure , Object , Object[] )
   en System.Web.Http.Controllers.ReflectedHttpActionDescriptor.ActionExecutor.<>c__DisplayClass10.<GetExecutor>b__9(Object instance, Object[] methodParameters)
   en System.Web.Http.Controllers.ReflectedHttpActionDescriptor.ExecuteAsync(HttpControllerContext controllerContext, IDictionary`2 arguments, CancellationToken cancellationToken)
--- Fin del seguimiento de la pila de la ubicación anterior donde se produjo la excepción ---
   en System.Runtime.CompilerServices.TaskAwaiter.ThrowForNonSuccess(Task task)
   en System.Runtime.CompilerServices.TaskAwaiter.HandleNonSuccessAndDebuggerNotification(Task task)
   en System.Web.Http.Controllers.ApiControllerActionInvoker.<InvokeActionAsyncCore>d__0.MoveNext()
--- Fin del seguimiento de la pila de la ubicación anterior donde se produjo la excepción ---
   en System.Runtime.CompilerServices.TaskAwaiter.ThrowForNonSuccess(Task task)
   en System.Runtime.CompilerServices.TaskAwaiter.HandleNonSuccessAndDebuggerNotification(Task task)
   en System.Web.Http.Filters.ActionFilterAttribute.<CallOnActionExecutedAsync>d__5.MoveNext()
--- Fin del seguimiento de la pila de la ubicación anterior donde se produjo la excepción ---
   en System.Web.Http.Filters.ActionFilterAttribute.<CallOnActionExecutedAsync>d__5.MoveNext()
--- Fin del seguimiento de la pila de la ubicación anterior donde se produjo la excepción ---
   en System.Runtime.CompilerServices.TaskAwaiter.ThrowForNonSuccess(Task task)
   en System.Runtime.CompilerServices.TaskAwaiter.HandleNonSuccessAndDebuggerNotification(Task task)
   en System.Web.Http.Filters.ActionFilterAttribute.<ExecuteActionFilterAsyncCore>d__0.MoveNext()
--- Fin del seguimiento de la pila de la ubicación anterior donde se produjo la excepción ---
   en System.Runtime.CompilerServices.TaskAwaiter.ThrowForNonSuccess(Task task)
   en System.Runtime.CompilerServices.TaskAwaiter.HandleNonSuccessAndDebuggerNotification(Task task)
   en System.Web.Http.Filters.ActionFilterAttribute.<CallOnActionExecutedAsync>d__5.MoveNext()
--- Fin del seguimiento de la pila de la ubicación anterior donde se produjo la excepción ---
   en System.Web.Http.Filters.ActionFilterAttribute.<CallOnActionExecutedAsync>d__5.MoveNext()
--- Fin del seguimiento de la pila de la ubicación anterior donde se produjo la excepción ---
   en System.Runtime.CompilerServices.TaskAwaiter.ThrowForNonSuccess(Task task)
   en System.Runtime.CompilerServices.TaskAwaiter.HandleNonSuccessAndDebuggerNotification(Task task)
   en System.Web.Http.Filters.ActionFilterAttribute.<ExecuteActionFilterAsyncCore>d__0.MoveNext()
--- Fin del seguimiento de la pila de la ubicación anterior donde se produjo la excepción ---
   en System.Runtime.CompilerServices.TaskAwaiter.ThrowForNonSuccess(Task task)
   en System.Runtime.CompilerServices.TaskAwaiter.HandleNonSuccessAndDebuggerNotification(Task task)
   en System.Web.Http.Controllers.ActionFilterResult.<ExecuteAsync>d__2.MoveNext()
--- Fin del seguimiento de la pila de la ubicación anterior donde se produjo la excepción ---
   en System.Runtime.CompilerServices.TaskAwaiter.ThrowForNonSuccess(Task task)
   en System.Runtime.CompilerServices.TaskAwaiter.HandleNonSuccessAndDebuggerNotification(Task task)
   en System.Web.Http.Controllers.AuthenticationFilterResult.<ExecuteAsync>d__0.MoveNext()
--- Fin del seguimiento de la pila de la ubicación anterior donde se produjo la excepción ---
   en System.Runtime.CompilerServices.TaskAwaiter.ThrowForNonSuccess(Task task)
   en System.Runtime.CompilerServices.TaskAwaiter.HandleNonSuccessAndDebuggerNotification(Task task)
   en System.Web.Http.Controllers.ExceptionFilterResult.<ExecuteAsync>d__0.MoveNext()
Status Code: InternalServerError
Internal Code: -2146233079
ReasonPhrase: InternalServerError
Message: The model backing the 'ServicioContext' context has changed since the database was created. Consider using Code First Migrations to update the database (http://go.microsoft.com/fwlink/?LinkId=238269).
Method: GET
URL: http://localhost:8105/api/books/
Controller : Servicio.Controllers.BooksController
Action : GetBooks
Action Parameters : {"messageFormat":"Resolver.Exceptions.ApiException: Se produjo una excepción de tipo 'Resolver.Exceptions.ApiException'.\r\n   en BusinessServices.BookServices.GetAll() en E:\\Servicio\\Peatonales\\PeatonalesRosario\\BusinessServices\\Services\\BookServices.cs:línea 70\r\n   en Servicio.Controllers.BooksController.GetBooks() en E:\\Servicio\\Peatonales\\PeatonalesRosario\\PeatonalesRosario\\Controllers\\BooksController.cs:línea 67\r\n   en lambda_method(Closure , Object , Object[] )\r\n   en System.Web.Http.Controllers.ReflectedHttpActionDescriptor.ActionExecutor.<>c__DisplayClass10.<GetExecutor>b__9(Object instance, Object[] methodParameters)\r\n   en System.Web.Http.Controllers.ReflectedHttpActionDescriptor.ExecuteAsync(HttpControllerContext controllerContext, IDictionary`2 arguments, CancellationToken cancellationToken)\r\n--- Fin del seguimiento de la pila de la ubicación anterior donde se produjo la excepción ---\r\n   en System.Runtime.CompilerServices.TaskAwaiter.ThrowForNonSuccess(Task task)\r\n   en System.Runtime.CompilerServices.TaskAwaiter.HandleNonSuccessAndDebuggerNotification(Task task)\r\n   en System.Web.Http.Controllers.ApiControllerActionInvoker.<InvokeActionAsyncCore>d__0.MoveNext()\r\n--- Fin del seguimiento de la pila de la ubicación anterior donde se produjo la excepción ---\r\n   en System.Runtime.CompilerServices.TaskAwaiter.ThrowForNonSuccess(Task task)\r\n   en System.Runtime.CompilerServices.TaskAwaiter.HandleNonSuccessAndDebuggerNotification(Task task)\r\n   en System.Web.Http.Filters.ActionFilterAttribute.<CallOnActionExecutedAsync>d__5.MoveNext()\r\n--- Fin del seguimiento de la pila de la ubicación anterior donde se produjo la excepción ---\r\n   en System.Web.Http.Filters.ActionFilterAttribute.<CallOnActionExecutedAsync>d__5.MoveNext()\r\n--- Fin del seguimiento de la pila de la ubicación anterior donde se produjo la excepción ---\r\n   en System.Runtime.CompilerServices.TaskAwaiter.ThrowForNonSuccess(Task task)\r\n   en System.Runtime.CompilerServices.TaskAwaiter.HandleNonSuccessAndDebuggerNotification(Task task)\r\n   en System.Web.Http.Filters.ActionFilterAttribute.<ExecuteActionFilterAsyncCore>d__0.MoveNext()\r\n--- Fin del seguimiento de la pila de la ubicación anterior donde se produjo la excepción ---\r\n   en System.Runtime.CompilerServices.TaskAwaiter.ThrowForNonSuccess(Task task)\r\n   en System.Runtime.CompilerServices.TaskAwaiter.HandleNonSuccessAndDebuggerNotification(Task task)\r\n   en System.Web.Http.Filters.ActionFilterAttribute.<CallOnActionExecutedAsync>d__5.MoveNext()\r\n--- Fin del seguimiento de la pila de la ubicación anterior donde se produjo la excepción ---\r\n   en System.Web.Http.Filters.ActionFilterAttribute.<CallOnActionExecutedAsync>d__5.MoveNext()\r\n--- Fin del seguimiento de la pila de la ubicación anterior donde se produjo la excepción ---\r\n   en System.Runtime.CompilerServices.TaskAwaiter.ThrowForNonSuccess(Task task)\r\n   en System.Runtime.CompilerServices.TaskAwaiter.HandleNonSuccessAndDebuggerNotification(Task task)\r\n   en System.Web.Http.Filters.ActionFilterAttribute.<ExecuteActionFilterAsyncCore>d__0.MoveNext()\r\n--- Fin del seguimiento de la pila de la ubicación anterior donde se produjo la excepción ---\r\n   en System.Runtime.CompilerServices.TaskAwaiter.ThrowForNonSuccess(Task task)\r\n   en System.Runtime.CompilerServices.TaskAwaiter.HandleNonSuccessAndDebuggerNotification(Task task)\r\n   en System.Web.Http.Controllers.ActionFilterResult.<ExecuteAsync>d__2.MoveNext()\r\n--- Fin del seguimiento de la pila de la ubicación anterior donde se produjo la excepción ---\r\n   en System.Runtime.CompilerServices.TaskAwaiter.ThrowForNonSuccess(Task task)\r\n   en System.Runtime.CompilerServices.TaskAwaiter.HandleNonSuccessAndDebuggerNotification(Task task)\r\n   en System.Web.Http.Controllers.AuthenticationFilterResult.<ExecuteAsync>d__0.MoveNext()\r\n--- Fin del seguimiento de la pila de la ubicación anterior donde se produjo la excepción ---\r\n   en System.Runtime.CompilerServices.TaskAwaiter.ThrowForNonSuccess(Task task)\r\n   en System.Runtime.CompilerServices.TaskAwaiter.HandleNonSuccessAndDebuggerNotification(Task task)\r\n   en System.Web.Http.Controllers.ExceptionFilterResult.<ExecuteAsync>d__0.MoveNext()\r\nStatus Code: InternalServerError\r\nInternal Code: -2146233079\r\nReasonPhrase: InternalServerError\r\nMessage: The model backing the 'ServicioContext' context has changed since the database was created. Consider using Code First Migrations to update the database (http://go.microsoft.com/fwlink/?LinkId=238269).","messageArguments":[]}

2018-05-12 14:50:05.7574|ERROR|Servicio.Helpers.NLogger|Resolver.Exceptions.ApiException: Se produjo una excepción de tipo 'Resolver.Exceptions.ApiException'.
   en BusinessServices.AuthorServices.GetAll(Int32 page, Int32 pageSize, String orderBy, String ascending, Int32& count) en E:\Servicio\Peatonales\PeatonalesRosario\BusinessServices\Services\AuthorServices.cs:línea 95
   en Servicio.Controllers.AuthorsController.<GetItems>d__2.MoveNext() en E:\Servicio\Peatonales\PeatonalesRosario\PeatonalesRosario\Controllers\AuthorsController.cs:línea 41
--- Fin del seguimiento de la pila de la ubicación anterior donde se produjo la excepción ---
   en System.Runtime.CompilerServices.TaskAwaiter.ThrowForNonSuccess(Task task)
   en System.Runtime.CompilerServices.TaskAwaiter.HandleNonSuccessAndDebuggerNotification(Task task)
   en System.Threading.Tasks.TaskHelpersExtensions.<CastToObject>d__3`1.MoveNext()
--- Fin del seguimiento de la pila de la ubicación anterior donde se produjo la excepción ---
   en System.Runtime.CompilerServices.TaskAwaiter.ThrowForNonSuccess(Task task)
   en System.Runtime.CompilerServices.TaskAwaiter.HandleNonSuccessAndDebuggerNotification(Task task)
   en System.Web.Http.Controllers.ApiControllerActionInvoker.<InvokeActionAsyncCore>d__0.MoveNext()
--- Fin del seguimiento de la pila de la ubicación anterior donde se produjo la excepción ---
   en System.Runtime.CompilerServices.TaskAwaiter.ThrowForNonSuccess(Task task)
   en System.Runtime.CompilerServices.TaskAwaiter.HandleNonSuccessAndDebuggerNotification(Task task)
   en System.Web.Http.Filters.ActionFilterAttribute.<CallOnActionExecutedAsync>d__5.MoveNext()
--- Fin del seguimiento de la pila de la ubicación anterior donde se produjo la excepción ---
   en System.Web.Http.Filters.ActionFilterAttribute.<CallOnActionExecutedAsync>d__5.MoveNext()
--- Fin del seguimiento de la pila de la ubicación anterior donde se produjo la excepción ---
   en System.Runtime.CompilerServices.TaskAwaiter.ThrowForNonSuccess(Task task)
   en System.Runtime.CompilerServices.TaskAwaiter.HandleNonSuccessAndDebuggerNotification(Task task)
   en System.Web.Http.Filters.ActionFilterAttribute.<ExecuteActionFilterAsyncCore>d__0.MoveNext()
--- Fin del seguimiento de la pila de la ubicación anterior donde se produjo la excepción ---
   en System.Runtime.CompilerServices.TaskAwaiter.ThrowForNonSuccess(Task task)
   en System.Runtime.CompilerServices.TaskAwaiter.HandleNonSuccessAndDebuggerNotification(Task task)
   en System.Web.Http.Controllers.ActionFilterResult.<ExecuteAsync>d__2.MoveNext()
--- Fin del seguimiento de la pila de la ubicación anterior donde se produjo la excepción ---
   en System.Runtime.CompilerServices.TaskAwaiter.ThrowForNonSuccess(Task task)
   en System.Runtime.CompilerServices.TaskAwaiter.HandleNonSuccessAndDebuggerNotification(Task task)
   en System.Web.Http.Controllers.AuthenticationFilterResult.<ExecuteAsync>d__0.MoveNext()
--- Fin del seguimiento de la pila de la ubicación anterior donde se produjo la excepción ---
   en System.Runtime.CompilerServices.TaskAwaiter.ThrowForNonSuccess(Task task)
   en System.Runtime.CompilerServices.TaskAwaiter.HandleNonSuccessAndDebuggerNotification(Task task)
   en System.Web.Http.Controllers.ExceptionFilterResult.<ExecuteAsync>d__0.MoveNext()
Status Code: InternalServerError
Internal Code: -2146233079
ReasonPhrase: InternalServerError
Message: The model backing the 'ServicioContext' context has changed since the database was created. Consider using Code First Migrations to update the database (http://go.microsoft.com/fwlink/?LinkId=238269).
Method: GET
URL: http://localhost:8105/api/authors/
Controller : Servicio.Controllers.AuthorsController
Action : GetItems
Action Parameters : {"messageFormat":"Resolver.Exceptions.ApiException: Se produjo una excepción de tipo 'Resolver.Exceptions.ApiException'.\r\n   en BusinessServices.AuthorServices.GetAll(Int32 page, Int32 pageSize, String orderBy, String ascending, Int32& count) en E:\\Servicio\\Peatonales\\PeatonalesRosario\\BusinessServices\\Services\\AuthorServices.cs:línea 95\r\n   en Servicio.Controllers.AuthorsController.<GetItems>d__2.MoveNext() en E:\\Servicio\\Peatonales\\PeatonalesRosario\\PeatonalesRosario\\Controllers\\AuthorsController.cs:línea 41\r\n--- Fin del seguimiento de la pila de la ubicación anterior donde se produjo la excepción ---\r\n   en System.Runtime.CompilerServices.TaskAwaiter.ThrowForNonSuccess(Task task)\r\n   en System.Runtime.CompilerServices.TaskAwaiter.HandleNonSuccessAndDebuggerNotification(Task task)\r\n   en System.Threading.Tasks.TaskHelpersExtensions.<CastToObject>d__3`1.MoveNext()\r\n--- Fin del seguimiento de la pila de la ubicación anterior donde se produjo la excepción ---\r\n   en System.Runtime.CompilerServices.TaskAwaiter.ThrowForNonSuccess(Task task)\r\n   en System.Runtime.CompilerServices.TaskAwaiter.HandleNonSuccessAndDebuggerNotification(Task task)\r\n   en System.Web.Http.Controllers.ApiControllerActionInvoker.<InvokeActionAsyncCore>d__0.MoveNext()\r\n--- Fin del seguimiento de la pila de la ubicación anterior donde se produjo la excepción ---\r\n   en System.Runtime.CompilerServices.TaskAwaiter.ThrowForNonSuccess(Task task)\r\n   en System.Runtime.CompilerServices.TaskAwaiter.HandleNonSuccessAndDebuggerNotification(Task task)\r\n   en System.Web.Http.Filters.ActionFilterAttribute.<CallOnActionExecutedAsync>d__5.MoveNext()\r\n--- Fin del seguimiento de la pila de la ubicación anterior donde se produjo la excepción ---\r\n   en System.Web.Http.Filters.ActionFilterAttribute.<CallOnActionExecutedAsync>d__5.MoveNext()\r\n--- Fin del seguimiento de la pila de la ubicación anterior donde se produjo la excepción ---\r\n   en System.Runtime.CompilerServices.TaskAwaiter.ThrowForNonSuccess(Task task)\r\n   en System.Runtime.CompilerServices.TaskAwaiter.HandleNonSuccessAndDebuggerNotification(Task task)\r\n   en System.Web.Http.Filters.ActionFilterAttribute.<ExecuteActionFilterAsyncCore>d__0.MoveNext()\r\n--- Fin del seguimiento de la pila de la ubicación anterior donde se produjo la excepción ---\r\n   en System.Runtime.CompilerServices.TaskAwaiter.ThrowForNonSuccess(Task task)\r\n   en System.Runtime.CompilerServices.TaskAwaiter.HandleNonSuccessAndDebuggerNotification(Task task)\r\n   en System.Web.Http.Controllers.ActionFilterResult.<ExecuteAsync>d__2.MoveNext()\r\n--- Fin del seguimiento de la pila de la ubicación anterior donde se produjo la excepción ---\r\n   en System.Runtime.CompilerServices.TaskAwaiter.ThrowForNonSuccess(Task task)\r\n   en System.Runtime.CompilerServices.TaskAwaiter.HandleNonSuccessAndDebuggerNotification(Task task)\r\n   en System.Web.Http.Controllers.AuthenticationFilterResult.<ExecuteAsync>d__0.MoveNext()\r\n--- Fin del seguimiento de la pila de la ubicación anterior donde se produjo la excepción ---\r\n   en System.Runtime.CompilerServices.TaskAwaiter.ThrowForNonSuccess(Task task)\r\n   en System.Runtime.CompilerServices.TaskAwaiter.HandleNonSuccessAndDebuggerNotification(Task task)\r\n   en System.Web.Http.Controllers.ExceptionFilterResult.<ExecuteAsync>d__0.MoveNext()\r\nStatus Code: InternalServerError\r\nInternal Code: -2146233079\r\nReasonPhrase: InternalServerError\r\nMessage: The model backing the 'ServicioContext' context has changed since the database was created. Consider using Code First Migrations to update the database (http://go.microsoft.com/fwlink/?LinkId=238269).","messageArguments":[]}

2018-05-12 16:49:16.7264|ERROR|Servicio.Helpers.NLogger|Resolver.Exceptions.ApiException: Se produjo una excepción de tipo 'Resolver.Exceptions.ApiException'.
   en Servicio.Controllers.AccountsController.<CreateUser>d__8.MoveNext() en E:\Servicio\Peatonales\PeatonalesRosario\PeatonalesRosario\Controllers\Security\AccountController.cs:línea 459
--- Fin del seguimiento de la pila de la ubicación anterior donde se produjo la excepción ---
   en System.Runtime.CompilerServices.TaskAwaiter.ThrowForNonSuccess(Task task)
   en System.Runtime.CompilerServices.TaskAwaiter.HandleNonSuccessAndDebuggerNotification(Task task)
   en System.Threading.Tasks.TaskHelpersExtensions.<CastToObject>d__3`1.MoveNext()
--- Fin del seguimiento de la pila de la ubicación anterior donde se produjo la excepción ---
   en System.Runtime.CompilerServices.TaskAwaiter.ThrowForNonSuccess(Task task)
   en System.Runtime.CompilerServices.TaskAwaiter.HandleNonSuccessAndDebuggerNotification(Task task)
   en System.Web.Http.Controllers.ApiControllerActionInvoker.<InvokeActionAsyncCore>d__0.MoveNext()
--- Fin del seguimiento de la pila de la ubicación anterior donde se produjo la excepción ---
   en System.Runtime.CompilerServices.TaskAwaiter.ThrowForNonSuccess(Task task)
   en System.Runtime.CompilerServices.TaskAwaiter.HandleNonSuccessAndDebuggerNotification(Task task)
   en System.Web.Http.Controllers.ActionFilterResult.<ExecuteAsync>d__2.MoveNext()
--- Fin del seguimiento de la pila de la ubicación anterior donde se produjo la excepción ---
   en System.Runtime.CompilerServices.TaskAwaiter.ThrowForNonSuccess(Task task)
   en System.Runtime.CompilerServices.TaskAwaiter.HandleNonSuccessAndDebuggerNotification(Task task)
   en System.Web.Http.Controllers.ExceptionFilterResult.<ExecuteAsync>d__0.MoveNext()
Status Code: InternalServerError
Internal Code: -2146232004
ReasonPhrase: InternalServerError
Message: An error occurred while executing the command definition. See the inner exception for details.
Method: POST
URL: http://localhost:8105/api/accounts/create
Controller : Servicio.Controllers.AccountsController
Action : CreateUser
Action Parameters : {"messageFormat":"Resolver.Exceptions.ApiException: Se produjo una excepción de tipo 'Resolver.Exceptions.ApiException'.\r\n   en Servicio.Controllers.AccountsController.<CreateUser>d__8.MoveNext() en E:\\Servicio\\Peatonales\\PeatonalesRosario\\PeatonalesRosario\\Controllers\\Security\\AccountController.cs:línea 459\r\n--- Fin del seguimiento de la pila de la ubicación anterior donde se produjo la excepción ---\r\n   en System.Runtime.CompilerServices.TaskAwaiter.ThrowForNonSuccess(Task task)\r\n   en System.Runtime.CompilerServices.TaskAwaiter.HandleNonSuccessAndDebuggerNotification(Task task)\r\n   en System.Threading.Tasks.TaskHelpersExtensions.<CastToObject>d__3`1.MoveNext()\r\n--- Fin del seguimiento de la pila de la ubicación anterior donde se produjo la excepción ---\r\n   en System.Runtime.CompilerServices.TaskAwaiter.ThrowForNonSuccess(Task task)\r\n   en System.Runtime.CompilerServices.TaskAwaiter.HandleNonSuccessAndDebuggerNotification(Task task)\r\n   en System.Web.Http.Controllers.ApiControllerActionInvoker.<InvokeActionAsyncCore>d__0.MoveNext()\r\n--- Fin del seguimiento de la pila de la ubicación anterior donde se produjo la excepción ---\r\n   en System.Runtime.CompilerServices.TaskAwaiter.ThrowForNonSuccess(Task task)\r\n   en System.Runtime.CompilerServices.TaskAwaiter.HandleNonSuccessAndDebuggerNotification(Task task)\r\n   en System.Web.Http.Controllers.ActionFilterResult.<ExecuteAsync>d__2.MoveNext()\r\n--- Fin del seguimiento de la pila de la ubicación anterior donde se produjo la excepción ---\r\n   en System.Runtime.CompilerServices.TaskAwaiter.ThrowForNonSuccess(Task task)\r\n   en System.Runtime.CompilerServices.TaskAwaiter.HandleNonSuccessAndDebuggerNotification(Task task)\r\n   en System.Web.Http.Controllers.ExceptionFilterResult.<ExecuteAsync>d__0.MoveNext()\r\nStatus Code: InternalServerError\r\nInternal Code: -2146232004\r\nReasonPhrase: InternalServerError\r\nMessage: An error occurred while executing the command definition. See the inner exception for details.","messageArguments":[]}

2018-05-12 16:50:15.8034|ERROR|Servicio.Helpers.NLogger|Resolver.Exceptions.ApiException: Se produjo una excepción de tipo 'Resolver.Exceptions.ApiException'.
   en Servicio.Controllers.AccountsController.<CreateUser>d__8.MoveNext() en E:\Servicio\Peatonales\PeatonalesRosario\PeatonalesRosario\Controllers\Security\AccountController.cs:línea 459
--- Fin del seguimiento de la pila de la ubicación anterior donde se produjo la excepción ---
   en System.Runtime.CompilerServices.TaskAwaiter.ThrowForNonSuccess(Task task)
   en System.Runtime.CompilerServices.TaskAwaiter.HandleNonSuccessAndDebuggerNotification(Task task)
   en System.Threading.Tasks.TaskHelpersExtensions.<CastToObject>d__3`1.MoveNext()
--- Fin del seguimiento de la pila de la ubicación anterior donde se produjo la excepción ---
   en System.Runtime.CompilerServices.TaskAwaiter.ThrowForNonSuccess(Task task)
   en System.Runtime.CompilerServices.TaskAwaiter.HandleNonSuccessAndDebuggerNotification(Task task)
   en System.Web.Http.Controllers.ApiControllerActionInvoker.<InvokeActionAsyncCore>d__0.MoveNext()
--- Fin del seguimiento de la pila de la ubicación anterior donde se produjo la excepción ---
   en System.Runtime.CompilerServices.TaskAwaiter.ThrowForNonSuccess(Task task)
   en System.Runtime.CompilerServices.TaskAwaiter.HandleNonSuccessAndDebuggerNotification(Task task)
   en System.Web.Http.Controllers.ActionFilterResult.<ExecuteAsync>d__2.MoveNext()
--- Fin del seguimiento de la pila de la ubicación anterior donde se produjo la excepción ---
   en System.Runtime.CompilerServices.TaskAwaiter.ThrowForNonSuccess(Task task)
   en System.Runtime.CompilerServices.TaskAwaiter.HandleNonSuccessAndDebuggerNotification(Task task)
   en System.Web.Http.Controllers.ExceptionFilterResult.<ExecuteAsync>d__0.MoveNext()
Status Code: InternalServerError
Internal Code: -2146232004
ReasonPhrase: InternalServerError
Message: An error occurred while executing the command definition. See the inner exception for details.
Method: POST
URL: http://localhost:8105/api/accounts/create
Controller : Servicio.Controllers.AccountsController
Action : CreateUser
Action Parameters : {"messageFormat":"Resolver.Exceptions.ApiException: Se produjo una excepción de tipo 'Resolver.Exceptions.ApiException'.\r\n   en Servicio.Controllers.AccountsController.<CreateUser>d__8.MoveNext() en E:\\Servicio\\Peatonales\\PeatonalesRosario\\PeatonalesRosario\\Controllers\\Security\\AccountController.cs:línea 459\r\n--- Fin del seguimiento de la pila de la ubicación anterior donde se produjo la excepción ---\r\n   en System.Runtime.CompilerServices.TaskAwaiter.ThrowForNonSuccess(Task task)\r\n   en System.Runtime.CompilerServices.TaskAwaiter.HandleNonSuccessAndDebuggerNotification(Task task)\r\n   en System.Threading.Tasks.TaskHelpersExtensions.<CastToObject>d__3`1.MoveNext()\r\n--- Fin del seguimiento de la pila de la ubicación anterior donde se produjo la excepción ---\r\n   en System.Runtime.CompilerServices.TaskAwaiter.ThrowForNonSuccess(Task task)\r\n   en System.Runtime.CompilerServices.TaskAwaiter.HandleNonSuccessAndDebuggerNotification(Task task)\r\n   en System.Web.Http.Controllers.ApiControllerActionInvoker.<InvokeActionAsyncCore>d__0.MoveNext()\r\n--- Fin del seguimiento de la pila de la ubicación anterior donde se produjo la excepción ---\r\n   en System.Runtime.CompilerServices.TaskAwaiter.ThrowForNonSuccess(Task task)\r\n   en System.Runtime.CompilerServices.TaskAwaiter.HandleNonSuccessAndDebuggerNotification(Task task)\r\n   en System.Web.Http.Controllers.ActionFilterResult.<ExecuteAsync>d__2.MoveNext()\r\n--- Fin del seguimiento de la pila de la ubicación anterior donde se produjo la excepción ---\r\n   en System.Runtime.CompilerServices.TaskAwaiter.ThrowForNonSuccess(Task task)\r\n   en System.Runtime.CompilerServices.TaskAwaiter.HandleNonSuccessAndDebuggerNotification(Task task)\r\n   en System.Web.Http.Controllers.ExceptionFilterResult.<ExecuteAsync>d__0.MoveNext()\r\nStatus Code: InternalServerError\r\nInternal Code: -2146232004\r\nReasonPhrase: InternalServerError\r\nMessage: An error occurred while executing the command definition. See the inner exception for details.","messageArguments":[]}

2018-05-12 16:51:34.4524|ERROR|Servicio.Helpers.NLogger|Resolver.Exceptions.ApiException: Se produjo una excepción de tipo 'Resolver.Exceptions.ApiException'.
   en Servicio.Controllers.AccountsController.<CreateUser>d__8.MoveNext() en E:\Servicio\Peatonales\PeatonalesRosario\PeatonalesRosario\Controllers\Security\AccountController.cs:línea 459
--- Fin del seguimiento de la pila de la ubicación anterior donde se produjo la excepción ---
   en System.Runtime.CompilerServices.TaskAwaiter.ThrowForNonSuccess(Task task)
   en System.Runtime.CompilerServices.TaskAwaiter.HandleNonSuccessAndDebuggerNotification(Task task)
   en System.Threading.Tasks.TaskHelpersExtensions.<CastToObject>d__3`1.MoveNext()
--- Fin del seguimiento de la pila de la ubicación anterior donde se produjo la excepción ---
   en System.Runtime.CompilerServices.TaskAwaiter.ThrowForNonSuccess(Task task)
   en System.Runtime.CompilerServices.TaskAwaiter.HandleNonSuccessAndDebuggerNotification(Task task)
   en System.Web.Http.Controllers.ApiControllerActionInvoker.<InvokeActionAsyncCore>d__0.MoveNext()
--- Fin del seguimiento de la pila de la ubicación anterior donde se produjo la excepción ---
   en System.Runtime.CompilerServices.TaskAwaiter.ThrowForNonSuccess(Task task)
   en System.Runtime.CompilerServices.TaskAwaiter.HandleNonSuccessAndDebuggerNotification(Task task)
   en System.Web.Http.Controllers.ActionFilterResult.<ExecuteAsync>d__2.MoveNext()
--- Fin del seguimiento de la pila de la ubicación anterior donde se produjo la excepción ---
   en System.Runtime.CompilerServices.TaskAwaiter.ThrowForNonSuccess(Task task)
   en System.Runtime.CompilerServices.TaskAwaiter.HandleNonSuccessAndDebuggerNotification(Task task)
   en System.Web.Http.Controllers.ExceptionFilterResult.<ExecuteAsync>d__0.MoveNext()
Status Code: InternalServerError
Internal Code: -2146232004
ReasonPhrase: InternalServerError
Message: An error occurred while executing the command definition. See the inner exception for details.
Method: POST
URL: http://localhost:8105/api/accounts/create
Controller : Servicio.Controllers.AccountsController
Action : CreateUser
Action Parameters : {"messageFormat":"Resolver.Exceptions.ApiException: Se produjo una excepción de tipo 'Resolver.Exceptions.ApiException'.\r\n   en Servicio.Controllers.AccountsController.<CreateUser>d__8.MoveNext() en E:\\Servicio\\Peatonales\\PeatonalesRosario\\PeatonalesRosario\\Controllers\\Security\\AccountController.cs:línea 459\r\n--- Fin del seguimiento de la pila de la ubicación anterior donde se produjo la excepción ---\r\n   en System.Runtime.CompilerServices.TaskAwaiter.ThrowForNonSuccess(Task task)\r\n   en System.Runtime.CompilerServices.TaskAwaiter.HandleNonSuccessAndDebuggerNotification(Task task)\r\n   en System.Threading.Tasks.TaskHelpersExtensions.<CastToObject>d__3`1.MoveNext()\r\n--- Fin del seguimiento de la pila de la ubicación anterior donde se produjo la excepción ---\r\n   en System.Runtime.CompilerServices.TaskAwaiter.ThrowForNonSuccess(Task task)\r\n   en System.Runtime.CompilerServices.TaskAwaiter.HandleNonSuccessAndDebuggerNotification(Task task)\r\n   en System.Web.Http.Controllers.ApiControllerActionInvoker.<InvokeActionAsyncCore>d__0.MoveNext()\r\n--- Fin del seguimiento de la pila de la ubicación anterior donde se produjo la excepción ---\r\n   en System.Runtime.CompilerServices.TaskAwaiter.ThrowForNonSuccess(Task task)\r\n   en System.Runtime.CompilerServices.TaskAwaiter.HandleNonSuccessAndDebuggerNotification(Task task)\r\n   en System.Web.Http.Controllers.ActionFilterResult.<ExecuteAsync>d__2.MoveNext()\r\n--- Fin del seguimiento de la pila de la ubicación anterior donde se produjo la excepción ---\r\n   en System.Runtime.CompilerServices.TaskAwaiter.ThrowForNonSuccess(Task task)\r\n   en System.Runtime.CompilerServices.TaskAwaiter.HandleNonSuccessAndDebuggerNotification(Task task)\r\n   en System.Web.Http.Controllers.ExceptionFilterResult.<ExecuteAsync>d__0.MoveNext()\r\nStatus Code: InternalServerError\r\nInternal Code: -2146232004\r\nReasonPhrase: InternalServerError\r\nMessage: An error occurred while executing the command definition. See the inner exception for details.","messageArguments":[]}

2018-05-12 16:53:23.0854|ERROR|Servicio.Helpers.NLogger|Resolver.Exceptions.ApiException: Se produjo una excepción de tipo 'Resolver.Exceptions.ApiException'.
   en Servicio.Controllers.AccountsController.<CreateUser>d__8.MoveNext() en E:\Servicio\Peatonales\PeatonalesRosario\PeatonalesRosario\Controllers\Security\AccountController.cs:línea 459
--- Fin del seguimiento de la pila de la ubicación anterior donde se produjo la excepción ---
   en System.Runtime.CompilerServices.TaskAwaiter.ThrowForNonSuccess(Task task)
   en System.Runtime.CompilerServices.TaskAwaiter.HandleNonSuccessAndDebuggerNotification(Task task)
   en System.Threading.Tasks.TaskHelpersExtensions.<CastToObject>d__3`1.MoveNext()
--- Fin del seguimiento de la pila de la ubicación anterior donde se produjo la excepción ---
   en System.Runtime.CompilerServices.TaskAwaiter.ThrowForNonSuccess(Task task)
   en System.Runtime.CompilerServices.TaskAwaiter.HandleNonSuccessAndDebuggerNotification(Task task)
   en System.Web.Http.Controllers.ApiControllerActionInvoker.<InvokeActionAsyncCore>d__0.MoveNext()
--- Fin del seguimiento de la pila de la ubicación anterior donde se produjo la excepción ---
   en System.Runtime.CompilerServices.TaskAwaiter.ThrowForNonSuccess(Task task)
   en System.Runtime.CompilerServices.TaskAwaiter.HandleNonSuccessAndDebuggerNotification(Task task)
   en System.Web.Http.Controllers.ActionFilterResult.<ExecuteAsync>d__2.MoveNext()
--- Fin del seguimiento de la pila de la ubicación anterior donde se produjo la excepción ---
   en System.Runtime.CompilerServices.TaskAwaiter.ThrowForNonSuccess(Task task)
   en System.Runtime.CompilerServices.TaskAwaiter.HandleNonSuccessAndDebuggerNotification(Task task)
   en System.Web.Http.Controllers.ExceptionFilterResult.<ExecuteAsync>d__0.MoveNext()
Status Code: InternalServerError
Internal Code: -2146232004
ReasonPhrase: InternalServerError
Message: An error occurred while executing the command definition. See the inner exception for details.
Method: POST
URL: http://localhost:8105/api/accounts/create
Controller : Servicio.Controllers.AccountsController
Action : CreateUser
Action Parameters : {"messageFormat":"Resolver.Exceptions.ApiException: Se produjo una excepción de tipo 'Resolver.Exceptions.ApiException'.\r\n   en Servicio.Controllers.AccountsController.<CreateUser>d__8.MoveNext() en E:\\Servicio\\Peatonales\\PeatonalesRosario\\PeatonalesRosario\\Controllers\\Security\\AccountController.cs:línea 459\r\n--- Fin del seguimiento de la pila de la ubicación anterior donde se produjo la excepción ---\r\n   en System.Runtime.CompilerServices.TaskAwaiter.ThrowForNonSuccess(Task task)\r\n   en System.Runtime.CompilerServices.TaskAwaiter.HandleNonSuccessAndDebuggerNotification(Task task)\r\n   en System.Threading.Tasks.TaskHelpersExtensions.<CastToObject>d__3`1.MoveNext()\r\n--- Fin del seguimiento de la pila de la ubicación anterior donde se produjo la excepción ---\r\n   en System.Runtime.CompilerServices.TaskAwaiter.ThrowForNonSuccess(Task task)\r\n   en System.Runtime.CompilerServices.TaskAwaiter.HandleNonSuccessAndDebuggerNotification(Task task)\r\n   en System.Web.Http.Controllers.ApiControllerActionInvoker.<InvokeActionAsyncCore>d__0.MoveNext()\r\n--- Fin del seguimiento de la pila de la ubicación anterior donde se produjo la excepción ---\r\n   en System.Runtime.CompilerServices.TaskAwaiter.ThrowForNonSuccess(Task task)\r\n   en System.Runtime.CompilerServices.TaskAwaiter.HandleNonSuccessAndDebuggerNotification(Task task)\r\n   en System.Web.Http.Controllers.ActionFilterResult.<ExecuteAsync>d__2.MoveNext()\r\n--- Fin del seguimiento de la pila de la ubicación anterior donde se produjo la excepción ---\r\n   en System.Runtime.CompilerServices.TaskAwaiter.ThrowForNonSuccess(Task task)\r\n   en System.Runtime.CompilerServices.TaskAwaiter.HandleNonSuccessAndDebuggerNotification(Task task)\r\n   en System.Web.Http.Controllers.ExceptionFilterResult.<ExecuteAsync>d__0.MoveNext()\r\nStatus Code: InternalServerError\r\nInternal Code: -2146232004\r\nReasonPhrase: InternalServerError\r\nMessage: An error occurred while executing the command definition. See the inner exception for details.","messageArguments":[]}

2018-05-12 16:57:15.6484|ERROR|Servicio.Helpers.NLogger|Resolver.Exceptions.ApiException: Se produjo una excepción de tipo 'Resolver.Exceptions.ApiException'.
   en Servicio.Controllers.AccountsController.<CreateUser>d__6.MoveNext() en E:\Servicio\Peatonales\PeatonalesRosario\PeatonalesRosario\Controllers\Security\AccountController.cs:línea 459
--- Fin del seguimiento de la pila de la ubicación anterior donde se produjo la excepción ---
   en System.Runtime.CompilerServices.TaskAwaiter.ThrowForNonSuccess(Task task)
   en System.Runtime.CompilerServices.TaskAwaiter.HandleNonSuccessAndDebuggerNotification(Task task)
   en System.Threading.Tasks.TaskHelpersExtensions.<CastToObject>d__3`1.MoveNext()
--- Fin del seguimiento de la pila de la ubicación anterior donde se produjo la excepción ---
   en System.Runtime.CompilerServices.TaskAwaiter.ThrowForNonSuccess(Task task)
   en System.Runtime.CompilerServices.TaskAwaiter.HandleNonSuccessAndDebuggerNotification(Task task)
   en System.Web.Http.Controllers.ApiControllerActionInvoker.<InvokeActionAsyncCore>d__0.MoveNext()
--- Fin del seguimiento de la pila de la ubicación anterior donde se produjo la excepción ---
   en System.Runtime.CompilerServices.TaskAwaiter.ThrowForNonSuccess(Task task)
   en System.Runtime.CompilerServices.TaskAwaiter.HandleNonSuccessAndDebuggerNotification(Task task)
   en System.Web.Http.Controllers.ActionFilterResult.<ExecuteAsync>d__2.MoveNext()
--- Fin del seguimiento de la pila de la ubicación anterior donde se produjo la excepción ---
   en System.Runtime.CompilerServices.TaskAwaiter.ThrowForNonSuccess(Task task)
   en System.Runtime.CompilerServices.TaskAwaiter.HandleNonSuccessAndDebuggerNotification(Task task)
   en System.Web.Http.Controllers.ExceptionFilterResult.<ExecuteAsync>d__0.MoveNext()
Status Code: InternalServerError
Internal Code: -2146232004
ReasonPhrase: InternalServerError
Message: An error occurred while executing the command definition. See the inner exception for details.
Method: POST
URL: http://localhost:8105/api/accounts/create
Controller : Servicio.Controllers.AccountsController
Action : CreateUser
Action Parameters : {"messageFormat":"Resolver.Exceptions.ApiException: Se produjo una excepción de tipo 'Resolver.Exceptions.ApiException'.\r\n   en Servicio.Controllers.AccountsController.<CreateUser>d__6.MoveNext() en E:\\Servicio\\Peatonales\\PeatonalesRosario\\PeatonalesRosario\\Controllers\\Security\\AccountController.cs:línea 459\r\n--- Fin del seguimiento de la pila de la ubicación anterior donde se produjo la excepción ---\r\n   en System.Runtime.CompilerServices.TaskAwaiter.ThrowForNonSuccess(Task task)\r\n   en System.Runtime.CompilerServices.TaskAwaiter.HandleNonSuccessAndDebuggerNotification(Task task)\r\n   en System.Threading.Tasks.TaskHelpersExtensions.<CastToObject>d__3`1.MoveNext()\r\n--- Fin del seguimiento de la pila de la ubicación anterior donde se produjo la excepción ---\r\n   en System.Runtime.CompilerServices.TaskAwaiter.ThrowForNonSuccess(Task task)\r\n   en System.Runtime.CompilerServices.TaskAwaiter.HandleNonSuccessAndDebuggerNotification(Task task)\r\n   en System.Web.Http.Controllers.ApiControllerActionInvoker.<InvokeActionAsyncCore>d__0.MoveNext()\r\n--- Fin del seguimiento de la pila de la ubicación anterior donde se produjo la excepción ---\r\n   en System.Runtime.CompilerServices.TaskAwaiter.ThrowForNonSuccess(Task task)\r\n   en System.Runtime.CompilerServices.TaskAwaiter.HandleNonSuccessAndDebuggerNotification(Task task)\r\n   en System.Web.Http.Controllers.ActionFilterResult.<ExecuteAsync>d__2.MoveNext()\r\n--- Fin del seguimiento de la pila de la ubicación anterior donde se produjo la excepción ---\r\n   en System.Runtime.CompilerServices.TaskAwaiter.ThrowForNonSuccess(Task task)\r\n   en System.Runtime.CompilerServices.TaskAwaiter.HandleNonSuccessAndDebuggerNotification(Task task)\r\n   en System.Web.Http.Controllers.ExceptionFilterResult.<ExecuteAsync>d__0.MoveNext()\r\nStatus Code: InternalServerError\r\nInternal Code: -2146232004\r\nReasonPhrase: InternalServerError\r\nMessage: An error occurred while executing the command definition. See the inner exception for details.","messageArguments":[]}

2018-05-12 16:59:47.9174|ERROR|Servicio.Helpers.NLogger|Resolver.Exceptions.ApiException: Se produjo una excepción de tipo 'Resolver.Exceptions.ApiException'.
   en Servicio.Controllers.AccountsController.<CreateUser>d__6.MoveNext() en E:\Servicio\Peatonales\PeatonalesRosario\PeatonalesRosario\Controllers\Security\AccountController.cs:línea 459
--- Fin del seguimiento de la pila de la ubicación anterior donde se produjo la excepción ---
   en System.Runtime.CompilerServices.TaskAwaiter.ThrowForNonSuccess(Task task)
   en System.Runtime.CompilerServices.TaskAwaiter.HandleNonSuccessAndDebuggerNotification(Task task)
   en System.Threading.Tasks.TaskHelpersExtensions.<CastToObject>d__3`1.MoveNext()
--- Fin del seguimiento de la pila de la ubicación anterior donde se produjo la excepción ---
   en System.Runtime.CompilerServices.TaskAwaiter.ThrowForNonSuccess(Task task)
   en System.Runtime.CompilerServices.TaskAwaiter.HandleNonSuccessAndDebuggerNotification(Task task)
   en System.Web.Http.Controllers.ApiControllerActionInvoker.<InvokeActionAsyncCore>d__0.MoveNext()
--- Fin del seguimiento de la pila de la ubicación anterior donde se produjo la excepción ---
   en System.Runtime.CompilerServices.TaskAwaiter.ThrowForNonSuccess(Task task)
   en System.Runtime.CompilerServices.TaskAwaiter.HandleNonSuccessAndDebuggerNotification(Task task)
   en System.Web.Http.Controllers.ActionFilterResult.<ExecuteAsync>d__2.MoveNext()
--- Fin del seguimiento de la pila de la ubicación anterior donde se produjo la excepción ---
   en System.Runtime.CompilerServices.TaskAwaiter.ThrowForNonSuccess(Task task)
   en System.Runtime.CompilerServices.TaskAwaiter.HandleNonSuccessAndDebuggerNotification(Task task)
   en System.Web.Http.Controllers.ExceptionFilterResult.<ExecuteAsync>d__0.MoveNext()
Status Code: InternalServerError
Internal Code: -2146232004
ReasonPhrase: InternalServerError
Message: An error occurred while executing the command definition. See the inner exception for details.
Method: POST
URL: http://localhost:8105/api/accounts/create
Controller : Servicio.Controllers.AccountsController
Action : CreateUser
Action Parameters : {"messageFormat":"Resolver.Exceptions.ApiException: Se produjo una excepción de tipo 'Resolver.Exceptions.ApiException'.\r\n   en Servicio.Controllers.AccountsController.<CreateUser>d__6.MoveNext() en E:\\Servicio\\Peatonales\\PeatonalesRosario\\PeatonalesRosario\\Controllers\\Security\\AccountController.cs:línea 459\r\n--- Fin del seguimiento de la pila de la ubicación anterior donde se produjo la excepción ---\r\n   en System.Runtime.CompilerServices.TaskAwaiter.ThrowForNonSuccess(Task task)\r\n   en System.Runtime.CompilerServices.TaskAwaiter.HandleNonSuccessAndDebuggerNotification(Task task)\r\n   en System.Threading.Tasks.TaskHelpersExtensions.<CastToObject>d__3`1.MoveNext()\r\n--- Fin del seguimiento de la pila de la ubicación anterior donde se produjo la excepción ---\r\n   en System.Runtime.CompilerServices.TaskAwaiter.ThrowForNonSuccess(Task task)\r\n   en System.Runtime.CompilerServices.TaskAwaiter.HandleNonSuccessAndDebuggerNotification(Task task)\r\n   en System.Web.Http.Controllers.ApiControllerActionInvoker.<InvokeActionAsyncCore>d__0.MoveNext()\r\n--- Fin del seguimiento de la pila de la ubicación anterior donde se produjo la excepción ---\r\n   en System.Runtime.CompilerServices.TaskAwaiter.ThrowForNonSuccess(Task task)\r\n   en System.Runtime.CompilerServices.TaskAwaiter.HandleNonSuccessAndDebuggerNotification(Task task)\r\n   en System.Web.Http.Controllers.ActionFilterResult.<ExecuteAsync>d__2.MoveNext()\r\n--- Fin del seguimiento de la pila de la ubicación anterior donde se produjo la excepción ---\r\n   en System.Runtime.CompilerServices.TaskAwaiter.ThrowForNonSuccess(Task task)\r\n   en System.Runtime.CompilerServices.TaskAwaiter.HandleNonSuccessAndDebuggerNotification(Task task)\r\n   en System.Web.Http.Controllers.ExceptionFilterResult.<ExecuteAsync>d__0.MoveNext()\r\nStatus Code: InternalServerError\r\nInternal Code: -2146232004\r\nReasonPhrase: InternalServerError\r\nMessage: An error occurred while executing the command definition. See the inner exception for details.","messageArguments":[]}

2018-05-12 17:01:36.4744|ERROR|Servicio.Helpers.NLogger|Resolver.Exceptions.ApiException: Se produjo una excepción de tipo 'Resolver.Exceptions.ApiException'.
   en Servicio.Controllers.AccountsController.<CreateUser>d__6.MoveNext() en E:\Servicio\Peatonales\PeatonalesRosario\PeatonalesRosario\Controllers\Security\AccountController.cs:línea 459
--- Fin del seguimiento de la pila de la ubicación anterior donde se produjo la excepción ---
   en System.Runtime.CompilerServices.TaskAwaiter.ThrowForNonSuccess(Task task)
   en System.Runtime.CompilerServices.TaskAwaiter.HandleNonSuccessAndDebuggerNotification(Task task)
   en System.Threading.Tasks.TaskHelpersExtensions.<CastToObject>d__3`1.MoveNext()
--- Fin del seguimiento de la pila de la ubicación anterior donde se produjo la excepción ---
   en System.Runtime.CompilerServices.TaskAwaiter.ThrowForNonSuccess(Task task)
   en System.Runtime.CompilerServices.TaskAwaiter.HandleNonSuccessAndDebuggerNotification(Task task)
   en System.Web.Http.Controllers.ApiControllerActionInvoker.<InvokeActionAsyncCore>d__0.MoveNext()
--- Fin del seguimiento de la pila de la ubicación anterior donde se produjo la excepción ---
   en System.Runtime.CompilerServices.TaskAwaiter.ThrowForNonSuccess(Task task)
   en System.Runtime.CompilerServices.TaskAwaiter.HandleNonSuccessAndDebuggerNotification(Task task)
   en System.Web.Http.Controllers.ActionFilterResult.<ExecuteAsync>d__2.MoveNext()
--- Fin del seguimiento de la pila de la ubicación anterior donde se produjo la excepción ---
   en System.Runtime.CompilerServices.TaskAwaiter.ThrowForNonSuccess(Task task)
   en System.Runtime.CompilerServices.TaskAwaiter.HandleNonSuccessAndDebuggerNotification(Task task)
   en System.Web.Http.Controllers.ExceptionFilterResult.<ExecuteAsync>d__0.MoveNext()
Status Code: InternalServerError
Internal Code: -2146232004
ReasonPhrase: InternalServerError
Message: An error occurred while executing the command definition. See the inner exception for details.
Method: POST
URL: http://localhost:8105/api/accounts/create
Controller : Servicio.Controllers.AccountsController
Action : CreateUser
Action Parameters : {"messageFormat":"Resolver.Exceptions.ApiException: Se produjo una excepción de tipo 'Resolver.Exceptions.ApiException'.\r\n   en Servicio.Controllers.AccountsController.<CreateUser>d__6.MoveNext() en E:\\Servicio\\Peatonales\\PeatonalesRosario\\PeatonalesRosario\\Controllers\\Security\\AccountController.cs:línea 459\r\n--- Fin del seguimiento de la pila de la ubicación anterior donde se produjo la excepción ---\r\n   en System.Runtime.CompilerServices.TaskAwaiter.ThrowForNonSuccess(Task task)\r\n   en System.Runtime.CompilerServices.TaskAwaiter.HandleNonSuccessAndDebuggerNotification(Task task)\r\n   en System.Threading.Tasks.TaskHelpersExtensions.<CastToObject>d__3`1.MoveNext()\r\n--- Fin del seguimiento de la pila de la ubicación anterior donde se produjo la excepción ---\r\n   en System.Runtime.CompilerServices.TaskAwaiter.ThrowForNonSuccess(Task task)\r\n   en System.Runtime.CompilerServices.TaskAwaiter.HandleNonSuccessAndDebuggerNotification(Task task)\r\n   en System.Web.Http.Controllers.ApiControllerActionInvoker.<InvokeActionAsyncCore>d__0.MoveNext()\r\n--- Fin del seguimiento de la pila de la ubicación anterior donde se produjo la excepción ---\r\n   en System.Runtime.CompilerServices.TaskAwaiter.ThrowForNonSuccess(Task task)\r\n   en System.Runtime.CompilerServices.TaskAwaiter.HandleNonSuccessAndDebuggerNotification(Task task)\r\n   en System.Web.Http.Controllers.ActionFilterResult.<ExecuteAsync>d__2.MoveNext()\r\n--- Fin del seguimiento de la pila de la ubicación anterior donde se produjo la excepción ---\r\n   en System.Runtime.CompilerServices.TaskAwaiter.ThrowForNonSuccess(Task task)\r\n   en System.Runtime.CompilerServices.TaskAwaiter.HandleNonSuccessAndDebuggerNotification(Task task)\r\n   en System.Web.Http.Controllers.ExceptionFilterResult.<ExecuteAsync>d__0.MoveNext()\r\nStatus Code: InternalServerError\r\nInternal Code: -2146232004\r\nReasonPhrase: InternalServerError\r\nMessage: An error occurred while executing the command definition. See the inner exception for details.","messageArguments":[]}

